Workbook
Name LIST_INDUSTRY: OFFSET('维度字典'!$A$2,0,0,COUNTA('维度字典'!$A$2:$A$200),1)
Name LIST_SALESPERSON: OFFSET('维度字典'!$C$2,0,0,COUNTA('维度字典'!$C$2:$C$200),1)
Name LIST_PRODUCT: OFFSET('维度字典'!$E$2,0,0,COUNTA('维度字典'!$E$2:$E$200),1)
Name LIST_REGION: OFFSET('维度字典'!$G$2,0,0,COUNTA('维度字典'!$G$2:$G$200),1)
Name LIST_METRIC_TARGET: OFFSET('维度字典'!$I$2,0,0,COUNTA('维度字典'!$I$2:$I$200),1)
Name LIST_METRIC_SYS: OFFSET('维度字典'!$M$2,0,0,COUNTA('维度字典'!$M$2:$M$200),1)
Name LIST_MONTH: '维度字典'!$U$2:$U$13

Sheet 填报指引
B2: 目标填报模板（SBU行业管理·按产品/行业/月份）v10
B3: 三层职责分离：目标填报（业务员唯一填报入口：年初设目标 + 月末填管道实际值）→ 系统实绩导入（管理员粘贴BI数据）→ 达成看板（全自动计算）
B5: 一、模板结构
B6: 「维度字典」维护行业/业务员/产品(钎焊、可拆)/区域/指标/参数，所有下拉自动联动。其中「目标填报指标」登记业务员可填报的全部 7 项指标及全年汇总方式；「实绩指标目录」只登记 BI 系统计算的指标（业务人员不填），是看板口径的权威清单。金额单位为万元。
B7: 「目标填报」业务员唯一填报表：每行 = 业务员×行业×产品×指标。①年初设定 5 类目标（销售目标额/毛利目标/毛利率目标/在手订单目标/目标客户机会目标），全年可修改，修改后所有达成率自动重算，并在「目标修订记录」列登记修改说明；②每月末在「在手订单」「目标客户机会」两行更新当月末最新实际值。
B8: 「系统实绩导入」BI 系统数据落地区：指标仅实绩销售额/实绩毛利，数据管理员每月从系统报表导出后粘贴当月列；业务人员不得修改。
B9: 「达成看板」全公式自动计算，无需填写：当期达成（本月销售额/毛利/毛利率/目标/达成率）、全年累计达成（累计/毛利率/年度目标/达成率/与目标差距）、管道充裕度（在手订单及目标与达成率、目标客户机会及目标与达成率）、下期预测（预测合计/剩余目标/预测达成率/预测与目标差距）；顶部可切换统计月份；组合行由维度字典自动展开，字典增删自动增减。
B10: 「经营汇总」产品×行业、业务员×产品、产品×月份、行业×月份 四块矩阵，公式自动。
B11: 「行业经营分析表」「业务员目标管理表」Word 样式汇报表，选月份/业务员后数字全自动。
B13: 二、填报规则（重点）
B14: 1. 一行 = 一个「业务员+行业+产品+指标」组合；同一组合同一指标只填一行，勿重复。
B15: 2. 目标填报：选好四个维度后，把 12 个月的值横向填入。目标类指标（销售/毛利/毛利率/在手订单目标/目标客户机会目标）年初设定、全年可改；「在手订单」「目标客户机会」为时点实际值，每月末只更新当月列。
... B42: 阈值在「维度字典」参数区维护（默认 黄线≥60%、绿线≥80%），改参数即全局生效，无需改任何公式。

Sheet 维度字典
A1: 行业维度（可增删） | C1: 业务员（可增删） | E1: 产品（钎焊/可拆，可扩展） | G1: 区域（预留） | I1: 目标填报指标 | J1: 汇总方式 | K1: 实绩指标目录（BI计算） | L1: 计算方式 | M1: 系统实绩指标 | N1: 汇总方式 | R1: 参数名 | S1: 参数值 | U1: 月份（固定1-12）
A2: 空调制冷 | C2: 张三 | E2: 钎焊 | G2: 华东 | I2: 销售目标额 | J2: 求和 | K2: 本月销售额 | L2: 系统计算 | M2: 实绩销售额 | N2: 求和 | R2: 目标年度（默认） | S2: 2027 | U2: 1
A3: 工业制冷 | C3: 李四 | E3: 可拆 | G3: 华南 | I3: 毛利目标 | J3: 求和 | K3: 本月毛利 | L3: 系统计算 | M3: 实绩毛利 | N3: 求和 | R3: 达成率·黄线（≥） | S3: 0.6 | U3: 2
A4: 船舶行业 | C4: 王五 | G4: 华北 | I4: 毛利率目标 | J4: 手工录入 | K4: 本月毛利率 | L4: 系统计算 | R4: 达成率·绿线（≥） | S4: 0.8 | U4: 3
A5: 储能行业 | I5: 在手订单目标 | J5: 最新值 | K5: 本月目标达成率 | L5: 系统计算 | R5: 金额单位 | S5: 万元 | U5: 4
A6: 数据中心 | I6: 目标客户机会目标 | J6: 最新值 | K6: 累计销售额 | L6: 系统计算 | U6: 5
I7: 在手订单 | J7: 最新值 | K7: 累计毛利 | L7: 系统计算 | U7: 6
I8: 目标客户机会 | J8: 最新值 | K8: 累计毛利率 | L8: 系统计算 | U8: 7
K9: 累计达成率 | L9: 系统计算 | U9: 8
K10: 与目标差距 | L10: 系统计算 | U10: 9
K11: 在手订单达成率 | L11: 系统计算 | U11: 10
K12: 目标客户机会达成率 | L12: 系统计算 | U12: 11
K13: 预测合计 | L13: 系统计算 | U13: 12
K14: 剩余目标 | L14: 系统计算
K15: 预测达成率 | L15: 系统计算
K16: 预测与目标差距 | L16: 系统计算

Sheet 目标填报
A1: 目标填报（按月）—— 业务员唯一填报入口：①年初设定5类目标（销售/毛利/毛利率/在手订单目标/目标客户机会目标，全年可改）；②每月末更新「在手订单」「目标客户机会」实际值
B2: 填报维度（下拉选择） | G2: 月度填报（万元）—— 当月填当列 | S2: 全年 | T2: 备注
A3: 序号 | B3: 业务员* | C3: 应用行业* | D3: 产品*(钎焊/可拆) | E3: 区域(预留) | F3: 填报指标* | G3: 1 | H3: 2 | I3: 3 | J3: 4 | K3: 5 | L3: 6 | M3: 7 | N3: 8 | O3: 9 | P3: 10 | Q3: 11 | R3: 12 | S3: 全年汇总 (自动/录入) | T3: 差异分析/备注 | U3: 目标修订记录
A4: =IF($B4="","",ROW()-3) | B4: 张三 | C4: 空调制冷 | D4: 钎焊 | E4: 华东 | F4: 销售目标额 | G4: 62 | H4: 53 | I4: 71 | J4: 79 | K4: 79 | L4: 88 | M4: 88 | N4: 79 | O4: 79 | P4: 79 | Q4: 71 | R4: 53 | S4: =IF($F4="","",IF(IFERROR(VLOOKUP($F4,'维度字典'!$I$2:$J$50,2,0),"求和")="手工录入","",IF(IFERROR(VLOOKUP($F4,'维度字典'!$I$2:$J$50,2,0),"求和")="最新值",IFERROR(LOOKUP(9.99E+307,G4:R4),""),SUM(G4:R4)))) | U4: 3月经营会调增：数据中心钎焊 +20
A5: =IF($B5="","",ROW()-3) | B5: 张三 | C5: 空调制冷 | D5: 钎焊 | E5: 华东 | F5: 毛利目标 | G5: 9.3 | H5: 7.9 | I5: 10.6 | J5: 11.9 | K5: 11.9 | L5: 13.2 | M5: 13.2 | N5: 11.9 | O5: 11.9 | P5: 11.9 | Q5: 10.6 | R5: 7.9 | S5: =IF($F5="","",IF(IFERROR(VLOOKUP($F5,'维度字典'!$I$2:$J$50,2,0),"求和")="手工录入","",IF(IFERROR(VLOOKUP($F5,'维度字典'!$I$2:$J$50,2,0),"求和")="最新值",IFERROR(LOOKUP(9.99E+307,G5:R5),""),SUM(G5:R5))))
A6: =IF($B6="","",ROW()-3) | B6: 张三 | C6: 空调制冷 | D6: 钎焊 | E6: 华东 | F6: 毛利率目标 | G6: 0.144 | H6: 0.1452 | I6: 0.1464 | J6: 0.1476 | K6: 0.1488 | L6: 0.15 | M6: 0.1512 | N6: 0.1524 | O6: 0.1536 | P6: 0.1548 | Q6: 0.156 | R6: 0.1572 | S6: 0.15
A7: =IF($B7="","",ROW()-3) | B7: 张三 | C7: 空调制冷 | D7: 钎焊 | E7: 华东 | F7: 在手订单目标 | G7: 104 | H7: 106 | I7: 107 | J7: 109 | K7: 110 | L7: 112 | M7: 113 | N7: 115 | O7: 116 | P7: 118 | Q7: 119 | R7: 121 | S7: =IF($F7="","",IF(IFERROR(VLOOKUP($F7,'维度字典'!$I$2:$J$50,2,0),"求和")="手工录入","",IF(IFERROR(VLOOKUP($F7,'维度字典'!$I$2:$J$50,2,0),"求和")="最新值",IFERROR(LOOKUP(9.99E+307,G7:R7),""),SUM(G7:R7)))) | U7: 6月调整：客户A项目延期，7-9月各 -10
A8: =IF($B8="","",ROW()-3) | B8: 张三 | C8: 空调制冷 | D8: 钎焊 | E8: 华东 | F8: 目标客户机会目标 | G8: 75 | H8: 76 | I8: 78 | J8: 79 | K8: 81 | L8: 82 | M8: 84 | N8: 85 | O8: 87 | P8: 88 | Q8: 90 | R8: 91 | S8: =IF($F8="","",IF(IFERROR(VLOOKUP($F8,'维度字典'!$I$2:$J$50,2,0),"求和")="手工录入","",IF(IFERROR(VLOOKUP($F8,'维度字典'!$I$2:$J$50,2,0),"求和")="最新值",IFERROR(LOOKUP(9.99E+307,G8:R8),""),SUM(G8:R8))))
A9: =IF($B9="","",ROW()-3) | B9: 张三 | C9: 空调制冷 | D9: 钎焊 | E9: 华东 | F9: 在手订单 | G9: 104 | H9: 106 | I9: 107 | J9: 109 | K9: 110 | L9: 112 | M9: 113 | N9: 115 | O9: 116 | P9: 118 | Q9: 119 | R9: 121 | S9: =IF($F9="","",IF(IFERROR(VLOOKUP($F9,'维度字典'!$I$2:$J$50,2,0),"求和")="手工录入","",IF(IFERROR(VLOOKUP($F9,'维度字典'!$I$2:$J$50,2,0),"求和")="最新值",IFERROR(LOOKUP(9.99E+307,G9:R9),""),SUM(G9:R9)))) | T9: 管道充足：大客户在手订单集中，交付节奏稳定
A10: =IF($B10="","",ROW()-3) | B10: 张三 | C10: 空调制冷 | D10: 钎焊 | E10: 华东 | F10: 目标客户机会 | G10: 64 | H10: 65 | I10: 66 | J10: 67 | K10: 69 | L10: 70 | M10: 71 | N10: 72 | O10: 74 | P10: 75 | Q10: 77 | R10: 77 | S10: =IF($F10="","",IF(IFERROR(VLOOKUP($F10,'维度字典'!$I$2:$J$50,2,0),"求和")="手工录入","",IF(IFERROR(VLOOKUP($F10,'维度字典'!$I$2:$J$50,2,0),"求和")="最新值",IFERROR(LOOKUP(9.99E+307,G10:R10),""),SUM(G10:R10))))
A11: =IF($B11="","",ROW()-3) | B11: 张三 | C11: 空调制冷 | D11: 可拆 | E11: 华东 | F11: 销售目标额 | G11: 26 | H11: 23 | I11: 30 | J11: 34 | K11: 34 | L11: 38 | M11: 38 | N11: 34 | O11: 34 | P11: 34 | Q11: 30 | R11: 23 | S11: =IF($F11="","",IF(IFERROR(VLOOKUP($F11,'维度字典'!$I$2:$J$50,2,0),"求和")="手工录入","",IF(IFERROR(VLOOKUP($F11,'维度字典'!$I$2:$J$50,2,0),"求和")="最新值",IFERROR(LOOKUP(9.99E+307,G11:R11),""),SUM(G11:R11))))
A12: =IF($B12="","",ROW()-3) | B12: 张三 | C12: 空调制冷 | D12: 可拆 | E12: 华东 | F12: 毛利目标 | G12: 4 | H12: 3.4 | I12: 4.5 | J12: 5.1 | K12: 5.1 | L12: 5.7 | M12: 5.7 | N12: 5.1 | O12: 5.1 | P12: 5.1 | Q12: 4.5 | R12: 3.4 | S12: =IF($F12="","",IF(IFERROR(VLOOKUP($F12,'维度字典'!$I$2:$J$50,2,0),"求和")="手工录入","",IF(IFERROR(VLOOKUP($F12,'维度字典'!$I$2:$J$50,2,0),"求和")="最新值",IFERROR(LOOKUP(9.99E+307,G12:R12),""),SUM(G12:R12))))
A13: =IF($B13="","",ROW()-3) | B13: 张三 | C13: 空调制冷 | D13: 可拆 | E13: 华东 | F13: 毛利率目标 | G13: 0.144 | H13: 0.1452 | I13: 0.1464 | J13: 0.1476 | K13: 0.1488 | L13: 0.15 | M13: 0.1512 | N13: 0.1524 | O13: 0.1536 | P13: 0.1548 | Q13: 0.156 | R13: 0.1572 | S13: 0.15
A14: =IF($B14="","",ROW()-3) | B14: 张三 | C14: 空调制冷 | D14: 可拆 | E14: 华东 | F14: 在手订单目标 | G14: 45 | H14: 45 | I14: 46 | J14: 47 | K14: 47 | L14: 48 | M14: 49 | N14: 49 | O14: 50 | P14: 50 | Q14: 51 | R14: 52 | S14: =IF($F14="","",IF(IFERROR(VLOOKUP($F14,'维度字典'!$I$2:$J$50,2,0),"求和")="手工录入","",IF(IFERROR(VLOOKUP($F14,'维度字典'!$I$2:$J$50,2,0),"求和")="最新值",IFERROR(LOOKUP(9.99E+307,G14:R14),""),SUM(G14:R14))))
A15: =IF($B15="","",ROW()-3) | B15: 张三 | C15: 空调制冷 | D15: 可拆 | E15: 华东 | F15: 目标客户机会目标 | G15: 32 | H15: 33 | I15: 33 | J15: 34 | K15: 35 | L15: 35 | M15: 36 | N15: 37 | O15: 37 | P15: 38 | Q15: 38 | R15: 39 | S15: =IF($F15="","",IF(IFERROR(VLOOKUP($F15,'维度字典'!$I$2:$J$50,2,0),"求和")="手工录入","",IF(IFERROR(VLOOKUP($F15,'维度字典'!$I$2:$J$50,2,0),"求和")="最新值",IFERROR(LOOKUP(9.99E+307,G15:R15),""),SUM(G15:R15))))
A16: =IF($B16="","",ROW()-3) | B16: 张三 | C16: 空调制冷 | D16: 可拆 | E16: 华东 | F16: 在手订单 | G16: 45 | H16: 45 | I16: 46 | J16: 47 | K16: 47 | L16: 48 | M16: 49 | N16: 49 | O16: 50 | P16: 50 | Q16: 51 | R16: 52 | S16: =IF($F16="","",IF(IFERROR(VLOOKUP($F16,'维度字典'!$I$2:$J$50,2,0),"求和")="手工录入","",IF(IFERROR(VLOOKUP($F16,'维度字典'!$I$2:$J$50,2,0),"求和")="最新值",IFERROR(LOOKUP(9.99E+307,G16:R16),""),SUM(G16:R16)))) | T16: 管道良好：新客户导入顺利，机会转化符合预期 | U16: 7月追加在手订单目标：空调制冷钎焊 +5
A17: =IF($B17="","",ROW()-3) | B17: 张三 | C17: 空调制冷 | D17: 可拆 | E17: 华东 | F17: 目标客户机会 | G17: 27 | H17: 28 | I17: 28 | J17: 29 | K17: 29 | L17: 29 | M17: 30 | N17: 31 | O17: 31 | P17: 32 | Q17: 32 | R17: 33 | S17: =IF($F17="","",IF(IFERROR(VLOOKUP($F17,'维度字典'!$I$2:$J$50,2,0),"求和")="手工录入","",IF(IFERROR(VLOOKUP($F17,'维度字典'!$I$2:$J$50,2,0),"求和")="最新值",IFERROR(LOOKUP(9.99E+307,G17:R17),""),SUM(G17:R17))))
A18: =IF($B18="","",ROW()-3) | B18: 张三 | C18: 工业制冷 | D18: 钎焊 | E18: 华东 | F18: 销售目标额 | G18: 37 | H18: 32 | I18: 42 | J18: 47 | K18: 47 | L18: 52 | M18: 52 | N18: 47 | O18: 47 | P18: 47 | Q18: 42 | R18: 32 | S18: =IF($F18="","",IF(IFERROR(VLOOKUP($F18,'维度字典'!$I$2:$J$50,2,0),"求和")="手工录入","",IF(IFERROR(VLOOKUP($F18,'维度字典'!$I$2:$J$50,2,0),"求和")="最新值",IFERROR(LOOKUP(9.99E+307,G18:R18),""),SUM(G18:R18))))
A19: =IF($B19="","",ROW()-3) | B19: 张三 | C19: 工业制冷 | D19: 钎焊 | E19: 华东 | F19: 毛利目标 | G19: 5.9 | H19: 5 | I19: 6.7 | J19: 7.6 | K19: 7.6 | L19: 8.4 | M19: 8.4 | N19: 7.6 | O19: 7.6 | P19: 7.6 | Q19: 6.7 | R19: 5 | S19: =IF($F19="","",IF(IFERROR(VLOOKUP($F19,'维度字典'!$I$2:$J$50,2,0),"求和")="手工录入","",IF(IFERROR(VLOOKUP($F19,'维度字典'!$I$2:$J$50,2,0),"求和")="最新值",IFERROR(LOOKUP(9.99E+307,G19:R19),""),SUM(G19:R19))))
A20: =IF($B20="","",ROW()-3) | B20: 张三 | C20: 工业制冷 | D20: 钎焊 | E20: 华东 | F20: 毛利率目标 | G20: 0.1536 | H20: 0.1549 | I20: 0.1562 | J20: 0.1574 | K20: 0.1587 | L20: 0.16 | M20: 0.1613 | N20: 0.1626 | O20: 0.1638 | P20: 0.1651 | Q20: 0.1664 | R20: 0.1677 | S20: 0.16
A21: =IF($B21="","",ROW()-3) | B21: 张三 | C21: 工业制冷 | D21: 钎焊 | E21: 华东 | F21: 在手订单目标 | G21: 62 | H21: 63 | I21: 64 | J21: 65 | K21: 66 | L21: 66 | M21: 67 | N21: 68 | O21: 69 | P21: 70 | Q21: 71 | R21: 72 | S21: =IF($F21="","",IF(IFERROR(VLOOKUP($F21,'维度字典'!$I$2:$J$50,2,0),"求和")="手工录入","",IF(IFERROR(VLOOKUP($F21,'维度字典'!$I$2:$J$50,2,0),"求和")="最新值",IFERROR(LOOKUP(9.99E+307,G21:R21),""),SUM(G21:R21))))
A22: =IF($B22="","",ROW()-3) | B22: 张三 | C22: 工业制冷 | D22: 钎焊 | E22: 华东 | F22: 目标客户机会目标 | G22: 45 | H22: 46 | I22: 46 | J22: 47 | K22: 48 | L22: 49 | M22: 50 | N22: 51 | O22: 52 | P22: 52 | Q22: 53 | R22: 54 | S22: =IF($F22="","",IF(IFERROR(VLOOKUP($F22,'维度字典'!$I$2:$J$50,2,0),"求和")="手工录入","",IF(IFERROR(VLOOKUP($F22,'维度字典'!$I$2:$J$50,2,0),"求和")="最新值",IFERROR(LOOKUP(9.99E+307,G22:R22),""),SUM(G22:R22))))
A23: =IF($B23="","",ROW()-3) | B23: 张三 | C23: 工业制冷 | D23: 钎焊 | E23: 华东 | F23: 在手订单 | G23: 62 | H23: 63 | I23: 64 | J23: 65 | K23: 66 | L23: 66 | M23: 67 | N23: 68 | O23: 69 | P23: 70 | Q23: 71 | R23: 72 | S23: =IF($F23="","",IF(IFERROR(VLOOKUP($F23,'维度字典'!$I$2:$J$50,2,0),"求和")="手工录入","",IF(IFERROR(VLOOKUP($F23,'维度字典'!$I$2:$J$50,2,0),"求和")="最新值",IFERROR(LOOKUP(9.99E+307,G23:R23),""),SUM(G23:R23)))) | T23: 管道充足：大客户在手订单集中，交付节奏稳定
A24: =IF($B24="","",ROW()-3) | B24: 张三 | C24: 工业制冷 | D24: 钎焊 | E24: 华东 | F24: 目标客户机会 | G24: 38 | H24: 39 | I24: 39 | J24: 40 | K24: 41 | L24: 42 | M24: 43 | N24: 43 | O24: 44 | P24: 44 | Q24: 45 | R24: 46 | S24: =IF($F24="","",IF(IFERROR(VLOOKUP($F24,'维度字典'!$I$2:$J$50,2,0),"求和")="手工录入","",IF(IFERROR(VLOOKUP($F24,'维度字典'!$I$2:$J$50,2,0),"求和")="最新值",IFERROR(LOOKUP(9.99E+307,G24:R24),""),SUM(G24:R24))))
A25: =IF($B25="","",ROW()-3) | B25: 张三 | C25: 工业制冷 | D25: 可拆 | E25: 华东 | F25: 销售目标额 | G25: 37 | H25: 32 | I25: 42 | J25: 47 | K25: 47 | L25: 52 | M25: 52 | N25: 47 | O25: 47 | P25: 47 | Q25: 42 | R25: 32 | S25: =IF($F25="","",IF(IFERROR(VLOOKUP($F25,'维度字典'!$I$2:$J$50,2,0),"求和")="手工录入","",IF(IFERROR(VLOOKUP($F25,'维度字典'!$I$2:$J$50,2,0),"求和")="最新值",IFERROR(LOOKUP(9.99E+307,G25:R25),""),SUM(G25:R25))))
A26: =IF($B26="","",ROW()-3) | B26: 张三 | C26: 工业制冷 | D26: 可拆 | E26: 华东 | F26: 毛利目标 | G26: 5.9 | H26: 5 | I26: 6.7 | J26: 7.6 | K26: 7.6 | L26: 8.4 | M26: 8.4 | N26: 7.6 | O26: 7.6 | P26: 7.6 | Q26: 6.7 | R26: 5 | S26: =IF($F26="","",IF(IFERROR(VLOOKUP($F26,'维度字典'!$I$2:$J$50,2,0),"求和")="手工录入","",IF(IFERROR(VLOOKUP($F26,'维度字典'!$I$2:$J$50,2,0),"求和")="最新值",IFERROR(LOOKUP(9.99E+307,G26:R26),""),SUM(G26:R26))))
A27: =IF($B27="","",ROW()-3) | B27: 张三 | C27: 工业制冷 | D27: 可拆 | E27: 华东 | F27: 毛利率目标 | G27: 0.1536 | H27: 0.1549 | I27: 0.1562 | J27: 0.1574 | K27: 0.1587 | L27: 0.16 | M27: 0.1613 | N27: 0.1626 | O27: 0.1638 | P27: 0.1651 | Q27: 0.1664 | R27: 0.1677 | S27: 0.16
A28: =IF($B28="","",ROW()-3) | B28: 张三 | C28: 工业制冷 | D28: 可拆 | E28: 华东 | F28: 在手订单目标 | G28: 62 | H28: 63 | I28: 64 | J28: 65 | K28: 66 | L28: 66 | M28: 67 | N28: 68 | O28: 69 | P28: 70 | Q28: 71 | R28: 72 | S28: =IF($F28="","",IF(IFERROR(VLOOKUP($F28,'维度字典'!$I$2:$J$50,2,0),"求和")="手工录入","",IF(IFERROR(VLOOKUP($F28,'维度字典'!$I$2:$J$50,2,0),"求和")="最新值",IFERROR(LOOKUP(9.99E+307,G28:R28),""),SUM(G28:R28))))
A29: =IF($B29="","",ROW()-3) | B29: 张三 | C29: 工业制冷 | D29: 可拆 | E29: 华东 | F29: 目标客户机会目标 | G29: 45 | H29: 46 | I29: 46 | J29: 47 | K29: 48 | L29: 49 | M29: 50 | N29: 51 | O29: 52 | P29: 52 | Q29: 53 | R29: 54 | S29: =IF($F29="","",IF(IFERROR(VLOOKUP($F29,'维度字典'!$I$2:$J$50,2,0),"求和")="手工录入","",IF(IFERROR(VLOOKUP($F29,'维度字典'!$I$2:$J$50,2,0),"求和")="最新值",IFERROR(LOOKUP(9.99E+307,G29:R29),""),SUM(G29:R29))))
A30: =IF($B30="","",ROW()-3) | B30: 张三 | C30: 工业制冷 | D30: 可拆 | E30: 华东 | F30: 在手订单 | G30: 62 | H30: 63 | I30: 64 | J30: 65 | K30: 66 | L30: 66 | M30: 67 | N30: 68 | O30: 69 | P30: 70 | Q30: 71 | R30: 72 | S30: =IF($F30="","",IF(IFERROR(VLOOKUP($F30,'维度字典'!$I$2:$J$50,2,0),"求和")="手工录入","",IF(IFERROR(VLOOKUP($F30,'维度字典'!$I$2:$J$50,2,0),"求和")="最新值",IFERROR(LOOKUP(9.99E+307,G30:R30),""),SUM(G30:R30)))) | T30: 管道充足：大客户在手订单集中，交付节奏稳定
A31: =IF($B31="","",ROW()-3) | B31: 张三 | C31: 工业制冷 | D31: 可拆 | E31: 华东 | F31: 目标客户机会 | G31: 38 | H31: 39 | I31: 39 | J31: 40 | K31: 41 | L31: 42 | M31: 43 | N31: 43 | O31: 44 | P31: 44 | Q31: 45 | R31: 46 | S31: =IF($F31="","",IF(IFERROR(VLOOKUP($F31,'维度字典'!$I$2:$J$50,2,0),"求和")="手工录入","",IF(IFERROR(VLOOKUP($F31,'维度字典'!$I$2:$J$50,2,0),"求和")="最新值",IFERROR(LOOKUP(9.99E+307,G31:R31),""),SUM(G31:R31))))
A32: =IF($B32="","",ROW()-3) | B32: 张三 | C32: 船舶行业 | D32: 钎焊 | E32: 华东 | F32: 销售目标额 | G32: 9 | H32: 8 | I32: 11 | J32: 12 | K32: 12 | L32: 13 | M32: 13 | N32: 12 | O32: 12 | P32: 12 | Q32: 11 | R32: 8 | S32: =IF($F32="","",IF(IFERROR(VLOOKUP($F32,'维度字典'!$I$2:$J$50,2,0),"求和")="手工录入","",IF(IFERROR(VLOOKUP($F32,'维度字典'!$I$2:$J$50,2,0),"求和")="最新值",IFERROR(LOOKUP(9.99E+307,G32:R32),""),SUM(G32:R32))))
A33: =IF($B33="","",ROW()-3) | B33: 张三 | C33: 船舶行业 | D33: 钎焊 | E33: 华东 | F33: 毛利目标 | G33: 1.9 | H33: 1.6 | I33: 2.1 | J33: 2.4 | K33: 2.4 | L33: 2.7 | M33: 2.7 | N33: 2.4 | O33: 2.4 | P33: 2.4 | Q33: 2.1 | R33: 1.6 | S33: =IF($F33="","",IF(IFERROR(VLOOKUP($F33,'维度字典'!$I$2:$J$50,2,0),"求和")="手工录入","",IF(IFERROR(VLOOKUP($F33,'维度字典'!$I$2:$J$50,2,0),"求和")="最新值",IFERROR(LOOKUP(9.99E+307,G33:R33),""),SUM(G33:R33))))
A34: =IF($B34="","",ROW()-3) | B34: 张三 | C34: 船舶行业 | D34: 钎焊 | E34: 华东 | F34: 毛利率目标 | G34: 0.192 | H34: 0.1936 | I34: 0.1952 | J34: 0.1968 | K34: 0.1984 | L34: 0.2 | M34: 0.2016 | N34: 0.2032 | O34: 0.2048 | P34: 0.2064 | Q34: 0.208 | R34: 0.2096 | S34: 0.2
A35: =IF($B35="","",ROW()-3) | B35: 张三 | C35: 船舶行业 | D35: 钎焊 | E35: 华东 | F35: 在手订单目标 | G35: 16 | H35: 16 | I35: 16 | J35: 17 | K35: 17 | L35: 17 | M35: 17 | N35: 17 | O35: 18 | P35: 18 | Q35: 18 | R35: 18 | S35: =IF($F35="","",IF(IFERROR(VLOOKUP($F35,'维度字典'!$I$2:$J$50,2,0),"求和")="手工录入","",IF(IFERROR(VLOOKUP($F35,'维度字典'!$I$2:$J$50,2,0),"求和")="最新值",IFERROR(LOOKUP(9.99E+307,G35:R35),""),SUM(G35:R35))))
A36: =IF($B36="","",ROW()-3) | B36: 张三 | C36: 船舶行业 | D36: 钎焊 | E36: 华东 | F36: 目标客户机会目标 | G36: 11 | H36: 12 | I36: 12 | J36: 12 | K36: 12 | L36: 13 | M36: 13 | N36: 13 | O36: 13 | P36: 13 | Q36: 14 | R36: 14 | S36: =IF($F36="","",IF(IFERROR(VLOOKUP($F36,'维度字典'!$I$2:$J$50,2,0),"求和")="手工录入","",IF(IFERROR(VLOOKUP($F36,'维度字典'!$I$2:$J$50,2,0),"求和")="最新值",IFERROR(LOOKUP(9.99E+307,G36:R36),""),SUM(G36:R36))))
A37: =IF($B37="","",ROW()-3) | B37: 张三 | C37: 船舶行业 | D37: 钎焊 | E37: 华东 | F37: 在手订单 | G37: 16 | H37: 16 | I37: 16 | J37: 17 | K37: 17 | L37: 17 | M37: 17 | N37: 17 | O37: 18 | P37: 18 | Q37: 18 | R37: 18 | S37: =IF($F37="","",IF(IFERROR(VLOOKUP($F37,'维度字典'!$I$2:$J$50,2,0),"求和")="手工录入","",IF(IFERROR(VLOOKUP($F37,'维度字典'!$I$2:$J$50,2,0),"求和")="最新值",IFERROR(LOOKUP(9.99E+307,G37:R37),""),SUM(G37:R37)))) | T37: 管道良好：新客户导入顺利，机会转化符合预期
A38: =IF($B38="","",ROW()-3) | B38: 张三 | C38: 船舶行业 | D38: 钎焊 | E38: 华东 | F38: 目标客户机会 | G38: 9 | H38: 10 | I38: 10 | J38: 10 | K38: 10 | L38: 11 | M38: 11 | N38: 11 | O38: 11 | P38: 11 | Q38: 12 | R38: 12 | S38: =IF($F38="","",IF(IFERROR(VLOOKUP($F38,'维度字典'!$I$2:$J$50,2,0),"求和")="手工录入","",IF(IFERROR(VLOOKUP($F38,'维度字典'!$I$2:$J$50,2,0),"求和")="最新值",IFERROR(LOOKUP(9.99E+307,G38:R38),""),SUM(G38:R38))))
A39: =IF($B39="","",ROW()-3) | B39: 张三 | C39: 船舶行业 | D39: 可拆 | E39: 华东 | F39: 销售目标额 | G39: 14 | H39: 12 | I39: 16 | J39: 18 | K39: 18 | L39: 20 | M39: 20 | N39: 18 | O39: 18 | P39: 18 | Q39: 16 | R39: 12 | S39: =IF($F39="","",IF(IFERROR(VLOOKUP($F39,'维度字典'!$I$2:$J$50,2,0),"求和")="手工录入","",IF(IFERROR(VLOOKUP($F39,'维度字典'!$I$2:$J$50,2,0),"求和")="最新值",IFERROR(LOOKUP(9.99E+307,G39:R39),""),SUM(G39:R39))))
A40: =IF($B40="","",ROW()-3) | B40: 张三 | C40: 船舶行业 | D40: 可拆 | E40: 华东 | F40: 毛利目标 | G40: 2.8 | H40: 2.4 | I40: 3.2 | J40: 3.6 | K40: 3.6 | L40: 4 | M40: 4 | N40: 3.6 | O40: 3.6 | P40: 3.6 | Q40: 3.2 | R40: 2.4 | S40: =IF($F40="","",IF(IFERROR(VLOOKUP($F40,'维度字典'!$I$2:$J$50,2,0),"求和")="手工录入","",IF(IFERROR(VLOOKUP($F40,'维度字典'!$I$2:$J$50,2,0),"求和")="最新值",IFERROR(LOOKUP(9.99E+307,G40:R40),""),SUM(G40:R40))))
...

Sheet 系统实绩导入
A1: 系统实绩导入（按月）—— BI系统数据落地区：数据管理员每月从系统导出后粘贴当月列；业务人员勿改
B2: 填报维度（下拉选择） | G2: 月度填报（万元）—— 当月填当列 | S2: 全年 | T2: 备注
A3: 序号 | B3: 业务员* | C3: 应用行业* | D3: 产品*(钎焊/可拆) | E3: 区域(预留) | F3: 填报指标* | G3: 1 | H3: 2 | I3: 3 | J3: 4 | K3: 5 | L3: 6 | M3: 7 | N3: 8 | O3: 9 | P3: 10 | Q3: 11 | R3: 12 | S3: 全年汇总 (自动/录入) | T3: 差异分析/备注
A4: =IF($B4="","",ROW()-3) | B4: 张三 | C4: 空调制冷 | D4: 钎焊 | E4: 华东 | F4: 实绩销售额 | G4: 62 | H4: 54 | I4: 71 | J4: 80 | K4: 80 | L4: 89 | M4: 89 | N4: 80 | O4: 80 | P4: 80 | Q4: 71 | R4: 54 | S4: =IF($F4="","",IF(IFERROR(VLOOKUP($F4,'维度字典'!$M$2:$N$50,2,0),"求和")="手工录入","",IF(IFERROR(VLOOKUP($F4,'维度字典'!$M$2:$N$50,2,0),"求和")="最新值",IFERROR(LOOKUP(9.99E+307,G4:R4),""),SUM(G4:R4))))
A5: =IF($B5="","",ROW()-3) | B5: 张三 | C5: 空调制冷 | D5: 钎焊 | E5: 华东 | F5: 实绩毛利 | G5: 9.3 | H5: 8.1 | I5: 10.7 | J5: 12 | K5: 12 | L5: 13.3 | M5: 13.3 | N5: 12 | O5: 12 | P5: 12 | Q5: 10.7 | R5: 8.1 | S5: =IF($F5="","",IF(IFERROR(VLOOKUP($F5,'维度字典'!$M$2:$N$50,2,0),"求和")="手工录入","",IF(IFERROR(VLOOKUP($F5,'维度字典'!$M$2:$N$50,2,0),"求和")="最新值",IFERROR(LOOKUP(9.99E+307,G5:R5),""),SUM(G5:R5))))
A6: =IF($B6="","",ROW()-3) | B6: 张三 | C6: 空调制冷 | D6: 可拆 | E6: 华东 | F6: 实绩销售额 | G6: 25 | H6: 22 | I6: 29 | J6: 33 | K6: 33 | L6: 36 | M6: 36 | N6: 33 | O6: 33 | P6: 33 | Q6: 29 | R6: 22 | S6: =IF($F6="","",IF(IFERROR(VLOOKUP($F6,'维度字典'!$M$2:$N$50,2,0),"求和")="手工录入","",IF(IFERROR(VLOOKUP($F6,'维度字典'!$M$2:$N$50,2,0),"求和")="最新值",IFERROR(LOOKUP(9.99E+307,G6:R6),""),SUM(G6:R6))))
A7: =IF($B7="","",ROW()-3) | B7: 张三 | C7: 空调制冷 | D7: 可拆 | E7: 华东 | F7: 实绩毛利 | G7: 3.8 | H7: 3.3 | I7: 4.3 | J7: 5 | K7: 5 | L7: 5.4 | M7: 5.4 | N7: 5 | O7: 5 | P7: 5 | Q7: 4.3 | R7: 3.3 | S7: =IF($F7="","",IF(IFERROR(VLOOKUP($F7,'维度字典'!$M$2:$N$50,2,0),"求和")="手工录入","",IF(IFERROR(VLOOKUP($F7,'维度字典'!$M$2:$N$50,2,0),"求和")="最新值",IFERROR(LOOKUP(9.99E+307,G7:R7),""),SUM(G7:R7))))
A8: =IF($B8="","",ROW()-3) | B8: 张三 | C8: 工业制冷 | D8: 钎焊 | E8: 华东 | F8: 实绩销售额 | G8: 39 | H8: 34 | I8: 45 | J8: 51 | K8: 51 | L8: 56 | M8: 56 | N8: 51 | O8: 51 | P8: 51 | Q8: 45 | R8: 34 | S8: =IF($F8="","",IF(IFERROR(VLOOKUP($F8,'维度字典'!$M$2:$N$50,2,0),"求和")="手工录入","",IF(IFERROR(VLOOKUP($F8,'维度字典'!$M$2:$N$50,2,0),"求和")="最新值",IFERROR(LOOKUP(9.99E+307,G8:R8),""),SUM(G8:R8))))
A9: =IF($B9="","",ROW()-3) | B9: 张三 | C9: 工业制冷 | D9: 钎焊 | E9: 华东 | F9: 实绩毛利 | G9: 6.2 | H9: 5.4 | I9: 7.2 | J9: 8.2 | K9: 8.2 | L9: 9 | M9: 9 | N9: 8.2 | O9: 8.2 | P9: 8.2 | Q9: 7.2 | R9: 5.4 | S9: =IF($F9="","",IF(IFERROR(VLOOKUP($F9,'维度字典'!$M$2:$N$50,2,0),"求和")="手工录入","",IF(IFERROR(VLOOKUP($F9,'维度字典'!$M$2:$N$50,2,0),"求和")="最新值",IFERROR(LOOKUP(9.99E+307,G9:R9),""),SUM(G9:R9))))
A10: =IF($B10="","",ROW()-3) | B10: 张三 | C10: 工业制冷 | D10: 可拆 | E10: 华东 | F10: 实绩销售额 | G10: 37 | H10: 32 | I10: 43 | J10: 48 | K10: 48 | L10: 54 | M10: 54 | N10: 48 | O10: 48 | P10: 48 | Q10: 43 | R10: 32 | S10: =IF($F10="","",IF(IFERROR(VLOOKUP($F10,'维度字典'!$M$2:$N$50,2,0),"求和")="手工录入","",IF(IFERROR(VLOOKUP($F10,'维度字典'!$M$2:$N$50,2,0),"求和")="最新值",IFERROR(LOOKUP(9.99E+307,G10:R10),""),SUM(G10:R10))))
A11: =IF($B11="","",ROW()-3) | B11: 张三 | C11: 工业制冷 | D11: 可拆 | E11: 华东 | F11: 实绩毛利 | G11: 5.9 | H11: 5.1 | I11: 6.9 | J11: 7.7 | K11: 7.7 | L11: 8.6 | M11: 8.6 | N11: 7.7 | O11: 7.7 | P11: 7.7 | Q11: 6.9 | R11: 5.1 | S11: =IF($F11="","",IF(IFERROR(VLOOKUP($F11,'维度字典'!$M$2:$N$50,2,0),"求和")="手工录入","",IF(IFERROR(VLOOKUP($F11,'维度字典'!$M$2:$N$50,2,0),"求和")="最新值",IFERROR(LOOKUP(9.99E+307,G11:R11),""),SUM(G11:R11))))
A12: =IF($B12="","",ROW()-3) | B12: 张三 | C12: 船舶行业 | D12: 钎焊 | E12: 华东 | F12: 实绩销售额 | G12: 9 | H12: 7 | I12: 10 | J12: 11 | K12: 11 | L12: 12 | M12: 12 | N12: 11 | O12: 11 | P12: 11 | Q12: 10 | R12: 7 | S12: =IF($F12="","",IF(IFERROR(VLOOKUP($F12,'维度字典'!$M$2:$N$50,2,0),"求和")="手工录入","",IF(IFERROR(VLOOKUP($F12,'维度字典'!$M$2:$N$50,2,0),"求和")="最新值",IFERROR(LOOKUP(9.99E+307,G12:R12),""),SUM(G12:R12))))
A13: =IF($B13="","",ROW()-3) | B13: 张三 | C13: 船舶行业 | D13: 钎焊 | E13: 华东 | F13: 实绩毛利 | G13: 1.8 | H13: 1.4 | I13: 2 | J13: 2.2 | K13: 2.2 | L13: 2.4 | M13: 2.4 | N13: 2.2 | O13: 2.2 | P13: 2.2 | Q13: 2 | R13: 1.4 | S13: =IF($F13="","",IF(IFERROR(VLOOKUP($F13,'维度字典'!$M$2:$N$50,2,0),"求和")="手工录入","",IF(IFERROR(VLOOKUP($F13,'维度字典'!$M$2:$N$50,2,0),"求和")="最新值",IFERROR(LOOKUP(9.99E+307,G13:R13),""),SUM(G13:R13))))
A14: =IF($B14="","",ROW()-3) | B14: 张三 | C14: 船舶行业 | D14: 可拆 | E14: 华东 | F14: 实绩销售额 | G14: 12 | H14: 10 | I14: 14 | J14: 16 | K14: 16 | L14: 17 | M14: 17 | N14: 16 | O14: 16 | P14: 16 | Q14: 14 | R14: 10 | S14: =IF($F14="","",IF(IFERROR(VLOOKUP($F14,'维度字典'!$M$2:$N$50,2,0),"求和")="手工录入","",IF(IFERROR(VLOOKUP($F14,'维度字典'!$M$2:$N$50,2,0),"求和")="最新值",IFERROR(LOOKUP(9.99E+307,G14:R14),""),SUM(G14:R14))))
A15: =IF($B15="","",ROW()-3) | B15: 张三 | C15: 船舶行业 | D15: 可拆 | E15: 华东 | F15: 实绩毛利 | G15: 2.4 | H15: 2 | I15: 2.8 | J15: 3.2 | K15: 3.2 | L15: 3.4 | M15: 3.4 | N15: 3.2 | O15: 3.2 | P15: 3.2 | Q15: 2.8 | R15: 2 | S15: =IF($F15="","",IF(IFERROR(VLOOKUP($F15,'维度字典'!$M$2:$N$50,2,0),"求和")="手工录入","",IF(IFERROR(VLOOKUP($F15,'维度字典'!$M$2:$N$50,2,0),"求和")="最新值",IFERROR(LOOKUP(9.99E+307,G15:R15),""),SUM(G15:R15))))
... A63: =IF($B63="","",ROW()-3) | B63: 王五 | C63: 数据中心 | D63: 可拆 | E63: 华北 | F63: 实绩毛利 | G63: 1.8 | H63: 1.3 | I63: 2 | J63: 2.2 | K63: 2.2 | L63: 2.4 | M63: 2.4 | N63: 2.2 | O63: 2.2 | P63: 2.2 | Q63: 2 | R63: 1.3 | S63: =IF($F63="","",IF(IFERROR(VLOOKUP($F63,'维度字典'!$M$2:$N$50,2,0),"求和")="手工录入","",IF(IFERROR(VLOOKUP($F63,'维度字典'!$M$2:$N$50,2,0),"求和")="最新值",IFERROR(LOOKUP(9.99E+307,G63:R63),""),SUM(G63:R63))))
A64: =IF($B64="","",ROW()-3) | S64: =IF($F64="","",IF(IFERROR(VLOOKUP($F64,'维度字典'!$M$2:$N$50,2,0),"求和")="手工录入","",IF(IFERROR(VLOOKUP($F64,'维度字典'!$M$2:$N$50,2,0),"求和")="最新值",IFERROR(LOOKUP(9.99E+307,G64:R64),""),SUM(G64:R64))))
A65: =IF($B65="","",ROW()-3) | S65: =IF($F65="","",IF(IFERROR(VLOOKUP($F65,'维度字典'!$M$2:$N$50,2,0),"求和")="手工录入","",IF(IFERROR(VLOOKUP($F65,'维度字典'!$M$2:$N$50,2,0),"求和")="最新值",IFERROR(LOOKUP(9.99E+307,G65:R65),""),SUM(G65:R65))))
A66: =IF($B66="","",ROW()-3) | S66: =IF($F66="","",IF(IFERROR(VLOOKUP($F66,'维度字典'!$M$2:$N$50,2,0),"求和")="手工录入","",IF(IFERROR(VLOOKUP($F66,'维度字典'!$M$2:$N$50,2,0),"求和")="最新值",IFERROR(LOOKUP(9.99E+307,G66:R66),""),SUM(G66:R66))))
A67: =IF($B67="","",ROW()-3) | S67: =IF($F67="","",IF(IFERROR(VLOOKUP($F67,'维度字典'!$M$2:$N$50,2,0),"求和")="手工录入","",IF(IFERROR(VLOOKUP($F67,'维度字典'!$M$2:$N$50,2,0),"求和")="最新值",IFERROR(LOOKUP(9.99E+307,G67:R67),""),SUM(G67:R67))))
A68: =IF($B68="","",ROW()-3) | S68: =IF($F68="","",IF(IFERROR(VLOOKUP($F68,'维度字典'!$M$2:$N$50,2,0),"求和")="手工录入","",IF(IFERROR(VLOOKUP($F68,'维度字典'!$M$2:$N$50,2,0),"求和")="最新值",IFERROR(LOOKUP(9.99E+307,G68:R68),""),SUM(G68:R68))))
A69: =IF($B69="","",ROW()-3) | S69: =IF($F69="","",IF(IFERROR(VLOOKUP($F69,'维度字典'!$M$2:$N$50,2,0),"求和")="手工录入","",IF(IFERROR(VLOOKUP($F69,'维度字典'!$M$2:$N$50,2,0),"求和")="最新值",IFERROR(LOOKUP(9.99E+307,G69:R69),""),SUM(G69:R69))))
A70: =IF($B70="","",ROW()-3) | S70: =IF($F70="","",IF(IFERROR(VLOOKUP($F70,'维度字典'!$M$2:$N$50,2,0),"求和")="手工录入","",IF(IFERROR(VLOOKUP($F70,'维度字典'!$M$2:$N$50,2,0),"求和")="最新值",IFERROR(LOOKUP(9.99E+307,G70:R70),""),SUM(G70:R70))))
A71: =IF($B71="","",ROW()-3) | S71: =IF($F71="","",IF(IFERROR(VLOOKUP($F71,'维度字典'!$M$2:$N$50,2,0),"求和")="手工录入","",IF(IFERROR(VLOOKUP($F71,'维度字典'!$M$2:$N$50,2,0),"求和")="最新值",IFERROR(LOOKUP(9.99E+307,G71:R71),""),SUM(G71:R71))))
A72: =IF($B72="","",ROW()-3) | S72: =IF($F72="","",IF(IFERROR(VLOOKUP($F72,'维度字典'!$M$2:$N$50,2,0),"求和")="手工录入","",IF(IFERROR(VLOOKUP($F72,'维度字典'!$M$2:$N$50,2,0),"求和")="最新值",IFERROR(LOOKUP(9.99E+307,G72:R72),""),SUM(G72:R72))))
A73: =IF($B73="","",ROW()-3) | S73: =IF($F73="","",IF(IFERROR(VLOOKUP($F73,'维度字典'!$M$2:$N$50,2,0),"求和")="手工录入","",IF(IFERROR(VLOOKUP($F73,'维度字典'!$M$2:$N$50,2,0),"求和")="最新值",IFERROR(LOOKUP(9.99E+307,G73:R73),""),SUM(G73:R73))))
A74: =IF($B74="","",ROW()-3) | S74: =IF($F74="","",IF(IFERROR(VLOOKUP($F74,'维度字典'!$M$2:$N$50,2,0),"求和")="手工录入","",IF(IFERROR(VLOOKUP($F74,'维度字典'!$M$2:$N$50,2,0),"求和")="最新值",IFERROR(LOOKUP(9.99E+307,G74:R74),""),SUM(G74:R74))))
A75: =IF($B75="","",ROW()-3) | S75: =IF($F75="","",IF(IFERROR(VLOOKUP($F75,'维度字典'!$M$2:$N$50,2,0),"求和")="手工录入","",IF(IFERROR(VLOOKUP($F75,'维度字典'!$M$2:$N$50,2,0),"求和")="最新值",IFERROR(LOOKUP(9.99E+307,G75:R75),""),SUM(G75:R75))))
... A1500: =IF($B1500="","",ROW()-3) | S1500: =IF($F1500="","",IF(IFERROR(VLOOKUP($F1500,'维度字典'!$M$2:$N$50,2,0),"求和")="手工录入","",IF(IFERROR(VLOOKUP($F1500,'维度字典'!$M$2:$N$50,2,0),"求和")="最新值",IFERROR(LOOKUP(9.99E+307,G1500:R1500),""),SUM(G1500:R1500))))

Sheet 达成看板
A1: 达成看板 —— 全部公式自动计算，无需填写（当期达成 / 全年累计达成 / 管道充裕度 / 下期预测） | E1: 统计月份(1-12)： | F1: 7
A2: 组合维度（字典自动展开） | E2: 当期达成（本月） | J2: 全年累计达成（1-X月） | P2: 管道充裕度（月末时点） | V2: 下期预测（在手+机会）
A3: 序号 | B3: 业务员 | C3: 应用行业 | D3: 产品 | E3: 本月销售额 | F3: 本月毛利 | G3: 本月毛利率 | H3: 本月目标 | I3: 本月目标达成率 | J3: 累计销售额 | K3: 累计毛利 | L3: 累计毛利率 | M3: 年度目标 | N3: 累计达成率 | O3: 与目标差距 | P3: 在手订单 | Q3: 在手订单目标 | R3: 在手订单达成率 | S3: 目标客户机会 | T3: 目标客户机会目标 | U3: 目标客户机会达成率 | V3: 预测合计 | W3: 剩余目标 | X3: 预测达成率 | Y3: 预测与目标差距
A4: =IF($B4="","",ROW()-3) | B4: =IF(0+1>COUNTA('维度字典'!$C$2:$C$200)*COUNTA('维度字典'!$A$2:$A$200)*COUNTA('维度字典'!$E$2:$E$200),"",INDEX('维度字典'!$C$2:$C$200,MOD(INT(0/(COUNTA('维度字典'!$E$2:$E$200)*COUNTA('维度字典'!$A$2:$A$200))),COUNTA('维度字典'!$C$2:$C$200))+1)) | C4: =IF($B4="","",INDEX('维度字典'!$A$2:$A$200,MOD(INT(0/COUNTA('维度字典'!$E$2:$E$200)),COUNTA('维度字典'!$A$2:$A$200))+1)) | D4: =IF($B4="","",INDEX('维度字典'!$E$2:$E$200,MOD(0,COUNTA('维度字典'!$E$2:$E$200))+1)) | E4: =IF($B4="","",SUMPRODUCT(('系统实绩导入'!$B$4:$B$1500=$B4)*('系统实绩导入'!$C$4:$C$1500=$C4)*('系统实绩导入'!$D$4:$D$1500=$D4)*('系统实绩导入'!$F$4:$F$1500="实绩销售额")*('系统实绩导入'!$G$3:$R$3=$F$1)*'系统实绩导入'!$G$4:$R$1500)) | F4: =IF($B4="","",SUMPRODUCT(('系统实绩导入'!$B$4:$B$1500=$B4)*('系统实绩导入'!$C$4:$C$1500=$C4)*('系统实绩导入'!$D$4:$D$1500=$D4)*('系统实绩导入'!$F$4:$F$1500="实绩毛利")*('系统实绩导入'!$G$3:$R$3=$F$1)*'系统实绩导入'!$G$4:$R$1500)) | G4: =IF($B4="","",IFERROR(F4/E4,"")) | H4: =IF($B4="","",SUMPRODUCT(('目标填报'!$B$4:$B$1500=$B4)*('目标填报'!$C$4:$C$1500=$C4)*('目标填报'!$D$4:$D$1500=$D4)*('目标填报'!$F$4:$F$1500="销售目标额")*('目标填报'!$G$3:$R$3=$F$1)*'目标填报'!$G$4:$R$1500)) | I4: =IF($B4="","",IFERROR(E4/H4,"")) | J4: =IF($B4="","",SUMPRODUCT(('系统实绩导入'!$B$4:$B$1500=$B4)*('系统实绩导入'!$C$4:$C$1500=$C4)*('系统实绩导入'!$D$4:$D$1500=$D4)*('系统实绩导入'!$F$4:$F$1500="实绩销售额")*('系统实绩导入'!$G$3:$R$3<=$F$1)*'系统实绩导入'!$G$4:$R$1500)) | K4: =IF($B4="","",SUMPRODUCT(('系统实绩导入'!$B$4:$B$1500=$B4)*('系统实绩导入'!$C$4:$C$1500=$C4)*('系统实绩导入'!$D$4:$D$1500=$D4)*('系统实绩导入'!$F$4:$F$1500="实绩毛利")*('系统实绩导入'!$G$3:$R$3<=$F$1)*'系统实绩导入'!$G$4:$R$1500)) | L4: =IF($B4="","",IFERROR(K4/J4,"")) | M4: =IF($B4="","",SUMIFS('目标填报'!$S$4:$S$1500,'目标填报'!$B$4:$B$1500,$B4,'目标填报'!$C$4:$C$1500,$C4,'目标填报'!$D$4:$D$1500,$D4,'目标填报'!$F$4:$F$1500,"销售目标额")) | N4: =IF($B4="","",IFERROR(J4/M4,"")) | O4: =IF($B4="","",J4-M4) | P4: =IF($B4="","",SUMPRODUCT(('目标填报'!$B$4:$B$1500=$B4)*('目标填报'!$C$4:$C$1500=$C4)*('目标填报'!$D$4:$D$1500=$D4)*('目标填报'!$F$4:$F$1500="在手订单")*('目标填报'!$G$3:$R$3=$F$1)*'目标填报'!$G$4:$R$1500)) | Q4: =IF($B4="","",SUMPRODUCT(('目标填报'!$B$4:$B$1500=$B4)*('目标填报'!$C$4:$C$1500=$C4)*('目标填报'!$D$4:$D$1500=$D4)*('目标填报'!$F$4:$F$1500="在手订单目标")*('目标填报'!$G$3:$R$3=$F$1)*'目标填报'!$G$4:$R$1500)) | R4: =IF($B4="","",IFERROR(P4/Q4,"")) | S4: =IF($B4="","",SUMPRODUCT(('目标填报'!$B$4:$B$1500=$B4)*('目标填报'!$C$4:$C$1500=$C4)*('目标填报'!$D$4:$D$1500=$D4)*('目标填报'!$F$4:$F$1500="目标客户机会")*('目标填报'!$G$3:$R$3=$F$1)*'目标填报'!$G$4:$R$1500)) | T4: =IF($B4="","",SUMPRODUCT(('目标填报'!$B$4:$B$1500=$B4)*('目标填报'!$C$4:$C$1500=$C4)*('目标填报'!$D$4:$D$1500=$D4)*('目标填报'!$F$4:$F$1500="目标客户机会目标")*('目标填报'!$G$3:$R$3=$F$1)*'目标填报'!$G$4:$R$1500)) | U4: =IF($B4="","",IFERROR(S4/T4,"")) | V4: =IF($B4="","",P4+S4) | W4: =IF($B4="","",M4-J4) | X4: =IF($B4="","",IFERROR(V4/W4,"")) | Y4: =IF($B4="","",V4-W4)
A5: =IF($B5="","",ROW()-3) | B5: =IF(1+1>COUNTA('维度字典'!$C$2:$C$200)*COUNTA('维度字典'!$A$2:$A$200)*COUNTA('维度字典'!$E$2:$E$200),"",INDEX('维度字典'!$C$2:$C$200,MOD(INT(1/(COUNTA('维度字典'!$E$2:$E$200)*COUNTA('维度字典'!$A$2:$A$200))),COUNTA('维度字典'!$C$2:$C$200))+1)) | C5: =IF($B5="","",INDEX('维度字典'!$A$2:$A$200,MOD(INT(1/COUNTA('维度字典'!$E$2:$E$200)),COUNTA('维度字典'!$A$2:$A$200))+1)) | D5: =IF($B5="","",INDEX('维度字典'!$E$2:$E$200,MOD(1,COUNTA('维度字典'!$E$2:$E$200))+1)) | E5: =IF($B5="","",SUMPRODUCT(('系统实绩导入'!$B$4:$B$1500=$B5)*('系统实绩导入'!$C$4:$C$1500=$C5)*('系统实绩导入'!$D$4:$D$1500=$D5)*('系统实绩导入'!$F$4:$F$1500="实绩销售额")*('系统实绩导入'!$G$3:$R$3=$F$1)*'系统实绩导入'!$G$4:$R$1500)) | F5: =IF($B5="","",SUMPRODUCT(('系统实绩导入'!$B$4:$B$1500=$B5)*('系统实绩导入'!$C$4:$C$1500=$C5)*('系统实绩导入'!$D$4:$D$1500=$D5)*('系统实绩导入'!$F$4:$F$1500="实绩毛利")*('系统实绩导入'!$G$3:$R$3=$F$1)*'系统实绩导入'!$G$4:$R$1500)) | G5: =IF($B5="","",IFERROR(F5/E5,"")) | H5: =IF($B5="","",SUMPRODUCT(('目标填报'!$B$4:$B$1500=$B5)*('目标填报'!$C$4:$C$1500=$C5)*('目标填报'!$D$4:$D$1500=$D5)*('目标填报'!$F$4:$F$1500="销售目标额")*('目标填报'!$G$3:$R$3=$F$1)*'目标填报'!$G$4:$R$1500)) | I5: =IF($B5="","",IFERROR(E5/H5,"")) | J5: =IF($B5="","",SUMPRODUCT(('系统实绩导入'!$B$4:$B$1500=$B5)*('系统实绩导入'!$C$4:$C$1500=$C5)*('系统实绩导入'!$D$4:$D$1500=$D5)*('系统实绩导入'!$F$4:$F$1500="实绩销售额")*('系统实绩导入'!$G$3:$R$3<=$F$1)*'系统实绩导入'!$G$4:$R$1500)) | K5: =IF($B5="","",SUMPRODUCT(('系统实绩导入'!$B$4:$B$1500=$B5)*('系统实绩导入'!$C$4:$C$1500=$C5)*('系统实绩导入'!$D$4:$D$1500=$D5)*('系统实绩导入'!$F$4:$F$1500="实绩毛利")*('系统实绩导入'!$G$3:$R$3<=$F$1)*'系统实绩导入'!$G$4:$R$1500)) | L5: =IF($B5="","",IFERROR(K5/J5,"")) | M5: =IF($B5="","",SUMIFS('目标填报'!$S$4:$S$1500,'目标填报'!$B$4:$B$1500,$B5,'目标填报'!$C$4:$C$1500,$C5,'目标填报'!$D$4:$D$1500,$D5,'目标填报'!$F$4:$F$1500,"销售目标额")) | N5: =IF($B5="","",IFERROR(J5/M5,"")) | O5: =IF($B5="","",J5-M5) | P5: =IF($B5="","",SUMPRODUCT(('目标填报'!$B$4:$B$1500=$B5)*('目标填报'!$C$4:$C$1500=$C5)*('目标填报'!$D$4:$D$1500=$D5)*('目标填报'!$F$4:$F$1500="在手订单")*('目标填报'!$G$3:$R$3=$F$1)*'目标填报'!$G$4:$R$1500)) | Q5: =IF($B5="","",SUMPRODUCT(('目标填报'!$B$4:$B$1500=$B5)*('目标填报'!$C$4:$C$1500=$C5)*('目标填报'!$D$4:$D$1500=$D5)*('目标填报'!$F$4:$F$1500="在手订单目标")*('目标填报'!$G$3:$R$3=$F$1)*'目标填报'!$G$4:$R$1500)) | R5: =IF($B5="","",IFERROR(P5/Q5,"")) | S5: =IF($B5="","",SUMPRODUCT(('目标填报'!$B$4:$B$1500=$B5)*('目标填报'!$C$4:$C$1500=$C5)*('目标填报'!$D$4:$D$1500=$D5)*('目标填报'!$F$4:$F$1500="目标客户机会")*('目标填报'!$G$3:$R$3=$F$1)*'目标填报'!$G$4:$R$1500)) | T5: =IF($B5="","",SUMPRODUCT(('目标填报'!$B$4:$B$1500=$B5)*('目标填报'!$C$4:$C$1500=$C5)*('目标填报'!$D$4:$D$1500=$D5)*('目标填报'!$F$4:$F$1500="目标客户机会目标")*('目标填报'!$G$3:$R$3=$F$1)*'目标填报'!$G$4:$R$1500)) | U5: =IF($B5="","",IFERROR(S5/T5,"")) | V5: =IF($B5="","",P5+S5) | W5: =IF($B5="","",M5-J5) | X5: =IF($B5="","",IFERROR(V5/W5,"")) | Y5: =IF($B5="","",V5-W5)
A6: =IF($B6="","",ROW()-3) | B6: =IF(2+1>COUNTA('维度字典'!$C$2:$C$200)*COUNTA('维度字典'!$A$2:$A$200)*COUNTA('维度字典'!$E$2:$E$200),"",INDEX('维度字典'!$C$2:$C$200,MOD(INT(2/(COUNTA('维度字典'!$E$2:$E$200)*COUNTA('维度字典'!$A$2:$A$200))),COUNTA('维度字典'!$C$2:$C$200))+1)) | C6: =IF($B6="","",INDEX('维度字典'!$A$2:$A$200,MOD(INT(2/COUNTA('维度字典'!$E$2:$E$200)),COUNTA('维度字典'!$A$2:$A$200))+1)) | D6: =IF($B6="","",INDEX('维度字典'!$E$2:$E$200,MOD(2,COUNTA('维度字典'!$E$2:$E$200))+1)) | E6: =IF($B6="","",SUMPRODUCT(('系统实绩导入'!$B$4:$B$1500=$B6)*('系统实绩导入'!$C$4:$C$1500=$C6)*('系统实绩导入'!$D$4:$D$1500=$D6)*('系统实绩导入'!$F$4:$F$1500="实绩销售额")*('系统实绩导入'!$G$3:$R$3=$F$1)*'系统实绩导入'!$G$4:$R$1500)) | F6: =IF($B6="","",SUMPRODUCT(('系统实绩导入'!$B$4:$B$1500=$B6)*('系统实绩导入'!$C$4:$C$1500=$C6)*('系统实绩导入'!$D$4:$D$1500=$D6)*('系统实绩导入'!$F$4:$F$1500="实绩毛利")*('系统实绩导入'!$G$3:$R$3=$F$1)*'系统实绩导入'!$G$4:$R$1500)) | G6: =IF($B6="","",IFERROR(F6/E6,"")) | H6: =IF($B6="","",SUMPRODUCT(('目标填报'!$B$4:$B$1500=$B6)*('目标填报'!$C$4:$C$1500=$C6)*('目标填报'!$D$4:$D$1500=$D6)*('目标填报'!$F$4:$F$1500="销售目标额")*('目标填报'!$G$3:$R$3=$F$1)*'目标填报'!$G$4:$R$1500)) | I6: =IF($B6="","",IFERROR(E6/H6,"")) | J6: =IF($B6="","",SUMPRODUCT(('系统实绩导入'!$B$4:$B$1500=$B6)*('系统实绩导入'!$C$4:$C$1500=$C6)*('系统实绩导入'!$D$4:$D$1500=$D6)*('系统实绩导入'!$F$4:$F$1500="实绩销售额")*('系统实绩导入'!$G$3:$R$3<=$F$1)*'系统实绩导入'!$G$4:$R$1500)) | K6: =IF($B6="","",SUMPRODUCT(('系统实绩导入'!$B$4:$B$1500=$B6)*('系统实绩导入'!$C$4:$C$1500=$C6)*('系统实绩导入'!$D$4:$D$1500=$D6)*('系统实绩导入'!$F$4:$F$1500="实绩毛利")*('系统实绩导入'!$G$3:$R$3<=$F$1)*'系统实绩导入'!$G$4:$R$1500)) | L6: =IF($B6="","",IFERROR(K6/J6,"")) | M6: =IF($B6="","",SUMIFS('目标填报'!$S$4:$S$1500,'目标填报'!$B$4:$B$1500,$B6,'目标填报'!$C$4:$C$1500,$C6,'目标填报'!$D$4:$D$1500,$D6,'目标填报'!$F$4:$F$1500,"销售目标额")) | N6: =IF($B6="","",IFERROR(J6/M6,"")) | O6: =IF($B6="","",J6-M6) | P6: =IF($B6="","",SUMPRODUCT(('目标填报'!$B$4:$B$1500=$B6)*('目标填报'!$C$4:$C$1500=$C6)*('目标填报'!$D$4:$D$1500=$D6)*('目标填报'!$F$4:$F$1500="在手订单")*('目标填报'!$G$3:$R$3=$F$1)*'目标填报'!$G$4:$R$1500)) | Q6: =IF($B6="","",SUMPRODUCT(('目标填报'!$B$4:$B$1500=$B6)*('目标填报'!$C$4:$C$1500=$C6)*('目标填报'!$D$4:$D$1500=$D6)*('目标填报'!$F$4:$F$1500="在手订单目标")*('目标填报'!$G$3:$R$3=$F$1)*'目标填报'!$G$4:$R$1500)) | R6: =IF($B6="","",IFERROR(P6/Q6,"")) | S6: =IF($B6="","",SUMPRODUCT(('目标填报'!$B$4:$B$1500=$B6)*('目标填报'!$C$4:$C$1500=$C6)*('目标填报'!$D$4:$D$1500=$D6)*('目标填报'!$F$4:$F$1500="目标客户机会")*('目标填报'!$G$3:$R$3=$F$1)*'目标填报'!$G$4:$R$1500)) | T6: =IF($B6="","",SUMPRODUCT(('目标填报'!$B$4:$B$1500=$B6)*('目标填报'!$C$4:$C$1500=$C6)*('目标填报'!$D$4:$D$1500=$D6)*('目标填报'!$F$4:$F$1500="目标客户机会目标")*('目标填报'!$G$3:$R$3=$F$1)*'目标填报'!$G$4:$R$1500)) | U6: =IF($B6="","",IFERROR(S6/T6,"")) | V6: =IF($B6="","",P6+S6) | W6: =IF($B6="","",M6-J6) | X6: =IF($B6="","",IFERROR(V6/W6,"")) | Y6: =IF($B6="","",V6-W6)
A7: =IF($B7="","",ROW()-3) | B7: =IF(3+1>COUNTA('维度字典'!$C$2:$C$200)*COUNTA('维度字典'!$A$2:$A$200)*COUNTA('维度字典'!$E$2:$E$200),"",INDEX('维度字典'!$C$2:$C$200,MOD(INT(3/(COUNTA('维度字典'!$E$2:$E$200)*COUNTA('维度字典'!$A$2:$A$200))),COUNTA('维度字典'!$C$2:$C$200))+1)) | C7: =IF($B7="","",INDEX('维度字典'!$A$2:$A$200,MOD(INT(3/COUNTA('维度字典'!$E$2:$E$200)),COUNTA('维度字典'!$A$2:$A$200))+1)) | D7: =IF($B7="","",INDEX('维度字典'!$E$2:$E$200,MOD(3,COUNTA('维度字典'!$E$2:$E$200))+1)) | E7: =IF($B7="","",SUMPRODUCT(('系统实绩导入'!$B$4:$B$1500=$B7)*('系统实绩导入'!$C$4:$C$1500=$C7)*('系统实绩导入'!$D$4:$D$1500=$D7)*('系统实绩导入'!$F$4:$F$1500="实绩销售额")*('系统实绩导入'!$G$3:$R$3=$F$1)*'系统实绩导入'!$G$4:$R$1500)) | F7: =IF($B7="","",SUMPRODUCT(('系统实绩导入'!$B$4:$B$1500=$B7)*('系统实绩导入'!$C$4:$C$1500=$C7)*('系统实绩导入'!$D$4:$D$1500=$D7)*('系统实绩导入'!$F$4:$F$1500="实绩毛利")*('系统实绩导入'!$G$3:$R$3=$F$1)*'系统实绩导入'!$G$4:$R$1500)) | G7: =IF($B7="","",IFERROR(F7/E7,"")) | H7: =IF($B7="","",SUMPRODUCT(('目标填报'!$B$4:$B$1500=$B7)*('目标填报'!$C$4:$C$1500=$C7)*('目标填报'!$D$4:$D$1500=$D7)*('目标填报'!$F$4:$F$1500="销售目标额")*('目标填报'!$G$3:$R$3=$F$1)*'目标填报'!$G$4:$R$1500)) | I7: =IF($B7="","",IFERROR(E7/H7,"")) | J7: =IF($B7="","",SUMPRODUCT(('系统实绩导入'!$B$4:$B$1500=$B7)*('系统实绩导入'!$C$4:$C$1500=$C7)*('系统实绩导入'!$D$4:$D$1500=$D7)*('系统实绩导入'!$F$4:$F$1500="实绩销售额")*('系统实绩导入'!$G$3:$R$3<=$F$1)*'系统实绩导入'!$G$4:$R$1500)) | K7: =IF($B7="","",SUMPRODUCT(('系统实绩导入'!$B$4:$B$1500=$B7)*('系统实绩导入'!$C$4:$C$1500=$C7)*('系统实绩导入'!$D$4:$D$1500=$D7)*('系统实绩导入'!$F$4:$F$1500="实绩毛利")*('系统实绩导入'!$G$3:$R$3<=$F$1)*'系统实绩导入'!$G$4:$R$1500)) | L7: =IF($B7="","",IFERROR(K7/J7,"")) | M7: =IF($B7="","",SUMIFS('目标填报'!$S$4:$S$1500,'目标填报'!$B$4:$B$1500,$B7,'目标填报'!$C$4:$C$1500,$C7,'目标填报'!$D$4:$D$1500,$D7,'目标填报'!$F$4:$F$1500,"销售目标额")) | N7: =IF($B7="","",IFERROR(J7/M7,"")) | O7: =IF($B7="","",J7-M7) | P7: =IF($B7="","",SUMPRODUCT(('目标填报'!$B$4:$B$1500=$B7)*('目标填报'!$C$4:$C$1500=$C7)*('目标填报'!$D$4:$D$1500=$D7)*('目标填报'!$F$4:$F$1500="在手订单")*('目标填报'!$G$3:$R$3=$F$1)*'目标填报'!$G$4:$R$1500)) | Q7: =IF($B7="","",SUMPRODUCT(('目标填报'!$B$4:$B$1500=$B7)*('目标填报'!$C$4:$C$1500=$C7)*('目标填报'!$D$4:$D$1500=$D7)*('目标填报'!$F$4:$F$1500="在手订单目标")*('目标填报'!$G$3:$R$3=$F$1)*'目标填报'!$G$4:$R$1500)) | R7: =IF($B7="","",IFERROR(P7/Q7,"")) | S7: =IF($B7="","",SUMPRODUCT(('目标填报'!$B$4:$B$1500=$B7)*('目标填报'!$C$4:$C$1500=$C7)*('目标填报'!$D$4:$D$1500=$D7)*('目标填报'!$F$4:$F$1500="目标客户机会")*('目标填报'!$G$3:$R$3=$F$1)*'目标填报'!$G$4:$R$1500)) | T7: =IF($B7="","",SUMPRODUCT(('目标填报'!$B$4:$B$1500=$B7)*('目标填报'!$C$4:$C$1500=$C7)*('目标填报'!$D$4:$D$1500=$D7)*('目标填报'!$F$4:$F$1500="目标客户机会目标")*('目标填报'!$G$3:$R$3=$F$1)*'目标填报'!$G$4:$R$1500)) | U7: =IF($B7="","",IFERROR(S7/T7,"")) | V7: =IF($B7="","",P7+S7) | W7: =IF($B7="","",M7-J7) | X7: =IF($B7="","",IFERROR(V7/W7,"")) | Y7: =IF($B7="","",V7-W7)
A8: =IF($B8="","",ROW()-3) | B8: =IF(4+1>COUNTA('维度字典'!$C$2:$C$200)*COUNTA('维度字典'!$A$2:$A$200)*COUNTA('维度字典'!$E$2:$E$200),"",INDEX('维度字典'!$C$2:$C$200,MOD(INT(4/(COUNTA('维度字典'!$E$2:$E$200)*COUNTA('维度字典'!$A$2:$A$200))),COUNTA('维度字典'!$C$2:$C$200))+1)) | C8: =IF($B8="","",INDEX('维度字典'!$A$2:$A$200,MOD(INT(4/COUNTA('维度字典'!$E$2:$E$200)),COUNTA('维度字典'!$A$2:$A$200))+1)) | D8: =IF($B8="","",INDEX('维度字典'!$E$2:$E$200,MOD(4,COUNTA('维度字典'!$E$2:$E$200))+1)) | E8: =IF($B8="","",SUMPRODUCT(('系统实绩导入'!$B$4:$B$1500=$B8)*('系统实绩导入'!$C$4:$C$1500=$C8)*('系统实绩导入'!$D$4:$D$1500=$D8)*('系统实绩导入'!$F$4:$F$1500="实绩销售额")*('系统实绩导入'!$G$3:$R$3=$F$1)*'系统实绩导入'!$G$4:$R$1500)) | F8: =IF($B8="","",SUMPRODUCT(('系统实绩导入'!$B$4:$B$1500=$B8)*('系统实绩导入'!$C$4:$C$1500=$C8)*('系统实绩导入'!$D$4:$D$1500=$D8)*('系统实绩导入'!$F$4:$F$1500="实绩毛利")*('系统实绩导入'!$G$3:$R$3=$F$1)*'系统实绩导入'!$G$4:$R$1500)) | G8: =IF($B8="","",IFERROR(F8/E8,"")) | H8: =IF($B8="","",SUMPRODUCT(('目标填报'!$B$4:$B$1500=$B8)*('目标填报'!$C$4:$C$1500=$C8)*('目标填报'!$D$4:$D$1500=$D8)*('目标填报'!$F$4:$F$1500="销售目标额")*('目标填报'!$G$3:$R$3=$F$1)*'目标填报'!$G$4:$R$1500)) | I8: =IF($B8="","",IFERROR(E8/H8,"")) | J8: =IF($B8="","",SUMPRODUCT(('系统实绩导入'!$B$4:$B$1500=$B8)*('系统实绩导入'!$C$4:$C$1500=$C8)*('系统实绩导入'!$D$4:$D$1500=$D8)*('系统实绩导入'!$F$4:$F$1500="实绩销售额")*('系统实绩导入'!$G$3:$R$3<=$F$1)*'系统实绩导入'!$G$4:$R$1500)) | K8: =IF($B8="","",SUMPRODUCT(('系统实绩导入'!$B$4:$B$1500=$B8)*('系统实绩导入'!$C$4:$C$1500=$C8)*('系统实绩导入'!$D$4:$D$1500=$D8)*('系统实绩导入'!$F$4:$F$1500="实绩毛利")*('系统实绩导入'!$G$3:$R$3<=$F$1)*'系统实绩导入'!$G$4:$R$1500)) | L8: =IF($B8="","",IFERROR(K8/J8,"")) | M8: =IF($B8="","",SUMIFS('目标填报'!$S$4:$S$1500,'目标填报'!$B$4:$B$1500,$B8,'目标填报'!$C$4:$C$1500,$C8,'目标填报'!$D$4:$D$1500,$D8,'目标填报'!$F$4:$F$1500,"销售目标额")) | N8: =IF($B8="","",IFERROR(J8/M8,"")) | O8: =IF($B8="","",J8-M8) | P8: =IF($B8="","",SUMPRODUCT(('目标填报'!$B$4:$B$1500=$B8)*('目标填报'!$C$4:$C$1500=$C8)*('目标填报'!$D$4:$D$1500=$D8)*('目标填报'!$F$4:$F$1500="在手订单")*('目标填报'!$G$3:$R$3=$F$1)*'目标填报'!$G$4:$R$1500)) | Q8: =IF($B8="","",SUMPRODUCT(('目标填报'!$B$4:$B$1500=$B8)*('目标填报'!$C$4:$C$1500=$C8)*('目标填报'!$D$4:$D$1500=$D8)*('目标填报'!$F$4:$F$1500="在手订单目标")*('目标填报'!$G$3:$R$3=$F$1)*'目标填报'!$G$4:$R$1500)) | R8: =IF($B8="","",IFERROR(P8/Q8,"")) | S8: =IF($B8="","",SUMPRODUCT(('目标填报'!$B$4:$B$1500=$B8)*('目标填报'!$C$4:$C$1500=$C8)*('目标填报'!$D$4:$D$1500=$D8)*('目标填报'!$F$4:$F$1500="目标客户机会")*('目标填报'!$G$3:$R$3=$F$1)*'目标填报'!$G$4:$R$1500)) | T8: =IF($B8="","",SUMPRODUCT(('目标填报'!$B$4:$B$1500=$B8)*('目标填报'!$C$4:$C$1500=$C8)*('目标填报'!$D$4:$D$1500=$D8)*('目标填报'!$F$4:$F$1500="目标客户机会目标")*('目标填报'!$G$3:$R$3=$F$1)*'目标填报'!$G$4:$R$1500)) | U8: =IF($B8="","",IFERROR(S8/T8,"")) | V8: =IF($B8="","",P8+S8) | W8: =IF($B8="","",M8-J8) | X8: =IF($B8="","",IFERROR(V8/W8,"")) | Y8: =IF($B8="","",V8-W8)
A9: =IF($B9="","",ROW()-3) | B9: =IF(5+1>COUNTA('维度字典'!$C$2:$C$200)*COUNTA('维度字典'!$A$2:$A$200)*COUNTA('维度字典'!$E$2:$E$200),"",INDEX('维度字典'!$C$2:$C$200,MOD(INT(5/(COUNTA('维度字典'!$E$2:$E$200)*COUNTA('维度字典'!$A$2:$A$200))),COUNTA('维度字典'!$C$2:$C$200))+1)) | C9: =IF($B9="","",INDEX('维度字典'!$A$2:$A$200,MOD(INT(5/COUNTA('维度字典'!$E$2:$E$200)),COUNTA('维度字典'!$A$2:$A$200))+1)) | D9: =IF($B9="","",INDEX('维度字典'!$E$2:$E$200,MOD(5,COUNTA('维度字典'!$E$2:$E$200))+1)) | E9: =IF($B9="","",SUMPRODUCT(('系统实绩导入'!$B$4:$B$1500=$B9)*('系统实绩导入'!$C$4:$C$1500=$C9)*('系统实绩导入'!$D$4:$D$1500=$D9)*('系统实绩导入'!$F$4:$F$1500="实绩销售额")*('系统实绩导入'!$G$3:$R$3=$F$1)*'系统实绩导入'!$G$4:$R$1500)) | F9: =IF($B9="","",SUMPRODUCT(('系统实绩导入'!$B$4:$B$1500=$B9)*('系统实绩导入'!$C$4:$C$1500=$C9)*('系统实绩导入'!$D$4:$D$1500=$D9)*('系统实绩导入'!$F$4:$F$1500="实绩毛利")*('系统实绩导入'!$G$3:$R$3=$F$1)*'系统实绩导入'!$G$4:$R$1500)) | G9: =IF($B9="","",IFERROR(F9/E9,"")) | H9: =IF($B9="","",SUMPRODUCT(('目标填报'!$B$4:$B$1500=$B9)*('目标填报'!$C$4:$C$1500=$C9)*('目标填报'!$D$4:$D$1500=$D9)*('目标填报'!$F$4:$F$1500="销售目标额")*('目标填报'!$G$3:$R$3=$F$1)*'目标填报'!$G$4:$R$1500)) | I9: =IF($B9="","",IFERROR(E9/H9,"")) | J9: =IF($B9="","",SUMPRODUCT(('系统实绩导入'!$B$4:$B$1500=$B9)*('系统实绩导入'!$C$4:$C$1500=$C9)*('系统实绩导入'!$D$4:$D$1500=$D9)*('系统实绩导入'!$F$4:$F$1500="实绩销售额")*('系统实绩导入'!$G$3:$R$3<=$F$1)*'系统实绩导入'!$G$4:$R$1500)) | K9: =IF($B9="","",SUMPRODUCT(('系统实绩导入'!$B$4:$B$1500=$B9)*('系统实绩导入'!$C$4:$C$1500=$C9)*('系统实绩导入'!$D$4:$D$1500=$D9)*('系统实绩导入'!$F$4:$F$1500="实绩毛利")*('系统实绩导入'!$G$3:$R$3<=$F$1)*'系统实绩导入'!$G$4:$R$1500)) | L9: =IF($B9="","",IFERROR(K9/J9,"")) | M9: =IF($B9="","",SUMIFS('目标填报'!$S$4:$S$1500,'目标填报'!$B$4:$B$1500,$B9,'目标填报'!$C$4:$C$1500,$C9,'目标填报'!$D$4:$D$1500,$D9,'目标填报'!$F$4:$F$1500,"销售目标额")) | N9: =IF($B9="","",IFERROR(J9/M9,"")) | O9: =IF($B9="","",J9-M9) | P9: =IF($B9="","",SUMPRODUCT(('目标填报'!$B$4:$B$1500=$B9)*('目标填报'!$C$4:$C$1500=$C9)*('目标填报'!$D$4:$D$1500=$D9)*('目标填报'!$F$4:$F$1500="在手订单")*('目标填报'!$G$3:$R$3=$F$1)*'目标填报'!$G$4:$R$1500)) | Q9: =IF($B9="","",SUMPRODUCT(('目标填报'!$B$4:$B$1500=$B9)*('目标填报'!$C$4:$C$1500=$C9)*('目标填报'!$D$4:$D$1500=$D9)*('目标填报'!$F$4:$F$1500="在手订单目标")*('目标填报'!$G$3:$R$3=$F$1)*'目标填报'!$G$4:$R$1500)) | R9: =IF($B9="","",IFERROR(P9/Q9,"")) | S9: =IF($B9="","",SUMPRODUCT(('目标填报'!$B$4:$B$1500=$B9)*('目标填报'!$C$4:$C$1500=$C9)*('目标填报'!$D$4:$D$1500=$D9)*('目标填报'!$F$4:$F$1500="目标客户机会")*('目标填报'!$G$3:$R$3=$F$1)*'目标填报'!$G$4:$R$1500)) | T9: =IF($B9="","",SUMPRODUCT(('目标填报'!$B$4:$B$1500=$B9)*('目标填报'!$C$4:$C$1500=$C9)*('目标填报'!$D$4:$D$1500=$D9)*('目标填报'!$F$4:$F$1500="目标客户机会目标")*('目标填报'!$G$3:$R$3=$F$1)*'目标填报'!$G$4:$R$1500)) | U9: =IF($B9="","",IFERROR(S9/T9,"")) | V9: =IF($B9="","",P9+S9) | W9: =IF($B9="","",M9-J9) | X9: =IF($B9="","",IFERROR(V9/W9,"")) | Y9: =IF($B9="","",V9-W9)
A10: =IF($B10="","",ROW()-3) | B10: =IF(6+1>COUNTA('维度字典'!$C$2:$C$200)*COUNTA('维度字典'!$A$2:$A$200)*COUNTA('维度字典'!$E$2:$E$200),"",INDEX('维度字典'!$C$2:$C$200,MOD(INT(6/(COUNTA('维度字典'!$E$2:$E$200)*COUNTA('维度字典'!$A$2:$A$200))),COUNTA('维度字典'!$C$2:$C$200))+1)) | C10: =IF($B10="","",INDEX('维度字典'!$A$2:$A$200,MOD(INT(6/COUNTA('维度字典'!$E$2:$E$200)),COUNTA('维度字典'!$A$2:$A$200))+1)) | D10: =IF($B10="","",INDEX('维度字典'!$E$2:$E$200,MOD(6,COUNTA('维度字典'!$E$2:$E$200))+1)) | E10: =IF($B10="","",SUMPRODUCT(('系统实绩导入'!$B$4:$B$1500=$B10)*('系统实绩导入'!$C$4:$C$1500=$C10)*('系统实绩导入'!$D$4:$D$1500=$D10)*('系统实绩导入'!$F$4:$F$1500="实绩销售额")*('系统实绩导入'!$G$3:$R$3=$F$1)*'系统实绩导入'!$G$4:$R$1500)) | F10: =IF($B10="","",SUMPRODUCT(('系统实绩导入'!$B$4:$B$1500=$B10)*('系统实绩导入'!$C$4:$C$1500=$C10)*('系统实绩导入'!$D$4:$D$1500=$D10)*('系统实绩导入'!$F$4:$F$1500="实绩毛利")*('系统实绩导入'!$G$3:$R$3=$F$1)*'系统实绩导入'!$G$4:$R$1500)) | G10: =IF($B10="","",IFERROR(F10/E10,"")) | H10: =IF($B10="","",SUMPRODUCT(('目标填报'!$B$4:$B$1500=$B10)*('目标填报'!$C$4:$C$1500=$C10)*('目标填报'!$D$4:$D$1500=$D10)*('目标填报'!$F$4:$F$1500="销售目标额")*('目标填报'!$G$3:$R$3=$F$1)*'目标填报'!$G$4:$R$1500)) | I10: =IF($B10="","",IFERROR(E10/H10,"")) | J10: =IF($B10="","",SUMPRODUCT(('系统实绩导入'!$B$4:$B$1500=$B10)*('系统实绩导入'!$C$4:$C$1500=$C10)*('系统实绩导入'!$D$4:$D$1500=$D10)*('系统实绩导入'!$F$4:$F$1500="实绩销售额")*('系统实绩导入'!$G$3:$R$3<=$F$1)*'系统实绩导入'!$G$4:$R$1500)) | K10: =IF($B10="","",SUMPRODUCT(('系统实绩导入'!$B$4:$B$1500=$B10)*('系统实绩导入'!$C$4:$C$1500=$C10)*('系统实绩导入'!$D$4:$D$1500=$D10)*('系统实绩导入'!$F$4:$F$1500="实绩毛利")*('系统实绩导入'!$G$3:$R$3<=$F$1)*'系统实绩导入'!$G$4:$R$1500)) | L10: =IF($B10="","",IFERROR(K10/J10,"")) | M10: =IF($B10="","",SUMIFS('目标填报'!$S$4:$S$1500,'目标填报'!$B$4:$B$1500,$B10,'目标填报'!$C$4:$C$1500,$C10,'目标填报'!$D$4:$D$1500,$D10,'目标填报'!$F$4:$F$1500,"销售目标额")) | N10: =IF($B10="","",IFERROR(J10/M10,"")) | O10: =IF($B10="","",J10-M10) | P10: =IF($B10="","",SUMPRODUCT(('目标填报'!$B$4:$B$1500=$B10)*('目标填报'!$C$4:$C$1500=$C10)*('目标填报'!$D$4:$D$1500=$D10)*('目标填报'!$F$4:$F$1500="在手订单")*('目标填报'!$G$3:$R$3=$F$1)*'目标填报'!$G$4:$R$1500)) | Q10: =IF($B10="","",SUMPRODUCT(('目标填报'!$B$4:$B$1500=$B10)*('目标填报'!$C$4:$C$1500=$C10)*('目标填报'!$D$4:$D$1500=$D10)*('目标填报'!$F$4:$F$1500="在手订单目标")*('目标填报'!$G$3:$R$3=$F$1)*'目标填报'!$G$4:$R$1500)) | R10: =IF($B10="","",IFERROR(P10/Q10,"")) | S10: =IF($B10="","",SUMPRODUCT(('目标填报'!$B$4:$B$1500=$B10)*('目标填报'!$C$4:$C$1500=$C10)*('目标填报'!$D$4:$D$1500=$D10)*('目标填报'!$F$4:$F$1500="目标客户机会")*('目标填报'!$G$3:$R$3=$F$1)*'目标填报'!$G$4:$R$1500)) | T10: =IF($B10="","",SUMPRODUCT(('目标填报'!$B$4:$B$1500=$B10)*('目标填报'!$C$4:$C$1500=$C10)*('目标填报'!$D$4:$D$1500=$D10)*('目标填报'!$F$4:$F$1500="目标客户机会目标")*('目标填报'!$G$3:$R$3=$F$1)*'目标填报'!$G$4:$R$1500)) | U10: =IF($B10="","",IFERROR(S10/T10,"")) | V10: =IF($B10="","",P10+S10) | W10: =IF($B10="","",M10-J10) | X10: =IF($B10="","",IFERROR(V10/W10,"")) | Y10: =IF($B10="","",V10-W10)
A11: =IF($B11="","",ROW()-3) | B11: =IF(7+1>COUNTA('维度字典'!$C$2:$C$200)*COUNTA('维度字典'!$A$2:$A$200)*COUNTA('维度字典'!$E$2:$E$200),"",INDEX('维度字典'!$C$2:$C$200,MOD(INT(7/(COUNTA('维度字典'!$E$2:$E$200)*COUNTA('维度字典'!$A$2:$A$200))),COUNTA('维度字典'!$C$2:$C$200))+1)) | C11: =IF($B11="","",INDEX('维度字典'!$A$2:$A$200,MOD(INT(7/COUNTA('维度字典'!$E$2:$E$200)),COUNTA('维度字典'!$A$2:$A$200))+1)) | D11: =IF($B11="","",INDEX('维度字典'!$E$2:$E$200,MOD(7,COUNTA('维度字典'!$E$2:$E$200))+1)) | E11: =IF($B11="","",SUMPRODUCT(('系统实绩导入'!$B$4:$B$1500=$B11)*('系统实绩导入'!$C$4:$C$1500=$C11)*('系统实绩导入'!$D$4:$D$1500=$D11)*('系统实绩导入'!$F$4:$F$1500="实绩销售额")*('系统实绩导入'!$G$3:$R$3=$F$1)*'系统实绩导入'!$G$4:$R$1500)) | F11: =IF($B11="","",SUMPRODUCT(('系统实绩导入'!$B$4:$B$1500=$B11)*('系统实绩导入'!$C$4:$C$1500=$C11)*('系统实绩导入'!$D$4:$D$1500=$D11)*('系统实绩导入'!$F$4:$F$1500="实绩毛利")*('系统实绩导入'!$G$3:$R$3=$F$1)*'系统实绩导入'!$G$4:$R$1500)) | G11: =IF($B11="","",IFERROR(F11/E11,"")) | H11: =IF($B11="","",SUMPRODUCT(('目标填报'!$B$4:$B$1500=$B11)*('目标填报'!$C$4:$C$1500=$C11)*('目标填报'!$D$4:$D$1500=$D11)*('目标填报'!$F$4:$F$1500="销售目标额")*('目标填报'!$G$3:$R$3=$F$1)*'目标填报'!$G$4:$R$1500)) | I11: =IF($B11="","",IFERROR(E11/H11,"")) | J11: =IF($B11="","",SUMPRODUCT(('系统实绩导入'!$B$4:$B$1500=$B11)*('系统实绩导入'!$C$4:$C$1500=$C11)*('系统实绩导入'!$D$4:$D$1500=$D11)*('系统实绩导入'!$F$4:$F$1500="实绩销售额")*('系统实绩导入'!$G$3:$R$3<=$F$1)*'系统实绩导入'!$G$4:$R$1500)) | K11: =IF($B11="","",SUMPRODUCT(('系统实绩导入'!$B$4:$B$1500=$B11)*('系统实绩导入'!$C$4:$C$1500=$C11)*('系统实绩导入'!$D$4:$D$1500=$D11)*('系统实绩导入'!$F$4:$F$1500="实绩毛利")*('系统实绩导入'!$G$3:$R$3<=$F$1)*'系统实绩导入'!$G$4:$R$1500)) | L11: =IF($B11="","",IFERROR(K11/J11,"")) | M11: =IF($B11="","",SUMIFS('目标填报'!$S$4:$S$1500,'目标填报'!$B$4:$B$1500,$B11,'目标填报'!$C$4:$C$1500,$C11,'目标填报'!$D$4:$D$1500,$D11,'目标填报'!$F$4:$F$1500,"销售目标额")) | N11: =IF($B11="","",IFERROR(J11/M11,"")) | O11: =IF($B11="","",J11-M11) | P11: =IF($B11="","",SUMPRODUCT(('目标填报'!$B$4:$B$1500=$B11)*('目标填报'!$C$4:$C$1500=$C11)*('目标填报'!$D$4:$D$1500=$D11)*('目标填报'!$F$4:$F$1500="在手订单")*('目标填报'!$G$3:$R$3=$F$1)*'目标填报'!$G$4:$R$1500)) | Q11: =IF($B11="","",SUMPRODUCT(('目标填报'!$B$4:$B$1500=$B11)*('目标填报'!$C$4:$C$1500=$C11)*('目标填报'!$D$4:$D$1500=$D11)*('目标填报'!$F$4:$F$1500="在手订单目标")*('目标填报'!$G$3:$R$3=$F$1)*'目标填报'!$G$4:$R$1500)) | R11: =IF($B11="","",IFERROR(P11/Q11,"")) | S11: =IF($B11="","",SUMPRODUCT(('目标填报'!$B$4:$B$1500=$B11)*('目标填报'!$C$4:$C$1500=$C11)*('目标填报'!$D$4:$D$1500=$D11)*('目标填报'!$F$4:$F$1500="目标客户机会")*('目标填报'!$G$3:$R$3=$F$1)*'目标填报'!$G$4:$R$1500)) | T11: =IF($B11="","",SUMPRODUCT(('目标填报'!$B$4:$B$1500=$B11)*('目标填报'!$C$4:$C$1500=$C11)*('目标填报'!$D$4:$D$1500=$D11)*('目标填报'!$F$4:$F$1500="目标客户机会目标")*('目标填报'!$G$3:$R$3=$F$1)*'目标填报'!$G$4:$R$1500)) | U11: =IF($B11="","",IFERROR(S11/T11,"")) | V11: =IF($B11="","",P11+S11) | W11: =IF($B11="","",M11-J11) | X11: =IF($B11="","",IFERROR(V11/W11,"")) | Y11: =IF($B11="","",V11-W11)
A12: =IF($B12="","",ROW()-3) | B12: =IF(8+1>COUNTA('维度字典'!$C$2:$C$200)*COUNTA('维度字典'!$A$2:$A$200)*COUNTA('维度字典'!$E$2:$E$200),"",INDEX('维度字典'!$C$2:$C$200,MOD(INT(8/(COUNTA('维度字典'!$E$2:$E$200)*COUNTA('维度字典'!$A$2:$A$200))),COUNTA('维度字典'!$C$2:$C$200))+1)) | C12: =IF($B12="","",INDEX('维度字典'!$A$2:$A$200,MOD(INT(8/COUNTA('维度字典'!$E$2:$E$200)),COUNTA('维度字典'!$A$2:$A$200))+1)) | D12: =IF($B12="","",INDEX('维度字典'!$E$2:$E$200,MOD(8,COUNTA('维度字典'!$E$2:$E$200))+1)) | E12: =IF($B12="","",SUMPRODUCT(('系统实绩导入'!$B$4:$B$1500=$B12)*('系统实绩导入'!$C$4:$C$1500=$C12)*('系统实绩导入'!$D$4:$D$1500=$D12)*('系统实绩导入'!$F$4:$F$1500="实绩销售额")*('系统实绩导入'!$G$3:$R$3=$F$1)*'系统实绩导入'!$G$4:$R$1500)) | F12: =IF($B12="","",SUMPRODUCT(('系统实绩导入'!$B$4:$B$1500=$B12)*('系统实绩导入'!$C$4:$C$1500=$C12)*('系统实绩导入'!$D$4:$D$1500=$D12)*('系统实绩导入'!$F$4:$F$1500="实绩毛利")*('系统实绩导入'!$G$3:$R$3=$F$1)*'系统实绩导入'!$G$4:$R$1500)) | G12: =IF($B12="","",IFERROR(F12/E12,"")) | H12: =IF($B12="","",SUMPRODUCT(('目标填报'!$B$4:$B$1500=$B12)*('目标填报'!$C$4:$C$1500=$C12)*('目标填报'!$D$4:$D$1500=$D12)*('目标填报'!$F$4:$F$1500="销售目标额")*('目标填报'!$G$3:$R$3=$F$1)*'目标填报'!$G$4:$R$1500)) | I12: =IF($B12="","",IFERROR(E12/H12,"")) | J12: =IF($B12="","",SUMPRODUCT(('系统实绩导入'!$B$4:$B$1500=$B12)*('系统实绩导入'!$C$4:$C$1500=$C12)*('系统实绩导入'!$D$4:$D$1500=$D12)*('系统实绩导入'!$F$4:$F$1500="实绩销售额")*('系统实绩导入'!$G$3:$R$3<=$F$1)*'系统实绩导入'!$G$4:$R$1500)) | K12: =IF($B12="","",SUMPRODUCT(('系统实绩导入'!$B$4:$B$1500=$B12)*('系统实绩导入'!$C$4:$C$1500=$C12)*('系统实绩导入'!$D$4:$D$1500=$D12)*('系统实绩导入'!$F$4:$F$1500="实绩毛利")*('系统实绩导入'!$G$3:$R$3<=$F$1)*'系统实绩导入'!$G$4:$R$1500)) | L12: =IF($B12="","",IFERROR(K12/J12,"")) | M12: =IF($B12="","",SUMIFS('目标填报'!$S$4:$S$1500,'目标填报'!$B$4:$B$1500,$B12,'目标填报'!$C$4:$C$1500,$C12,'目标填报'!$D$4:$D$1500,$D12,'目标填报'!$F$4:$F$1500,"销售目标额")) | N12: =IF($B12="","",IFERROR(J12/M12,"")) | O12: =IF($B12="","",J12-M12) | P12: =IF($B12="","",SUMPRODUCT(('目标填报'!$B$4:$B$1500=$B12)*('目标填报'!$C$4:$C$1500=$C12)*('目标填报'!$D$4:$D$1500=$D12)*('目标填报'!$F$4:$F$1500="在手订单")*('目标填报'!$G$3:$R$3=$F$1)*'目标填报'!$G$4:$R$1500)) | Q12: =IF($B12="","",SUMPRODUCT(('目标填报'!$B$4:$B$1500=$B12)*('目标填报'!$C$4:$C$1500=$C12)*('目标填报'!$D$4:$D$1500=$D12)*('目标填报'!$F$4:$F$1500="在手订单目标")*('目标填报'!$G$3:$R$3=$F$1)*'目标填报'!$G$4:$R$1500)) | R12: =IF($B12="","",IFERROR(P12/Q12,"")) | S12: =IF($B12="","",SUMPRODUCT(('目标填报'!$B$4:$B$1500=$B12)*('目标填报'!$C$4:$C$1500=$C12)*('目标填报'!$D$4:$D$1500=$D12)*('目标填报'!$F$4:$F$1500="目标客户机会")*('目标填报'!$G$3:$R$3=$F$1)*'目标填报'!$G$4:$R$1500)) | T12: =IF($B12="","",SUMPRODUCT(('目标填报'!$B$4:$B$1500=$B12)*('目标填报'!$C$4:$C$1500=$C12)*('目标填报'!$D$4:$D$1500=$D12)*('目标填报'!$F$4:$F$1500="目标客户机会目标")*('目标填报'!$G$3:$R$3=$F$1)*'目标填报'!$G$4:$R$1500)) | U12: =IF($B12="","",IFERROR(S12/T12,"")) | V12: =IF($B12="","",P12+S12) | W12: =IF($B12="","",M12-J12) | X12: =IF($B12="","",IFERROR(V12/W12,"")) | Y12: =IF($B12="","",V12-W12)
A13: =IF($B13="","",ROW()-3) | B13: =IF(9+1>COUNTA('维度字典'!$C$2:$C$200)*COUNTA('维度字典'!$A$2:$A$200)*COUNTA('维度字典'!$E$2:$E$200),"",INDEX('维度字典'!$C$2:$C$200,MOD(INT(9/(COUNTA('维度字典'!$E$2:$E$200)*COUNTA('维度字典'!$A$2:$A$200))),COUNTA('维度字典'!$C$2:$C$200))+1)) | C13: =IF($B13="","",INDEX('维度字典'!$A$2:$A$200,MOD(INT(9/COUNTA('维度字典'!$E$2:$E$200)),COUNTA('维度字典'!$A$2:$A$200))+1)) | D13: =IF($B13="","",INDEX('维度字典'!$E$2:$E$200,MOD(9,COUNTA('维度字典'!$E$2:$E$200))+1)) | E13: =IF($B13="","",SUMPRODUCT(('系统实绩导入'!$B$4:$B$1500=$B13)*('系统实绩导入'!$C$4:$C$1500=$C13)*('系统实绩导入'!$D$4:$D$1500=$D13)*('系统实绩导入'!$F$4:$F$1500="实绩销售额")*('系统实绩导入'!$G$3:$R$3=$F$1)*'系统实绩导入'!$G$4:$R$1500)) | F13: =IF($B13="","",SUMPRODUCT(('系统实绩导入'!$B$4:$B$1500=$B13)*('系统实绩导入'!$C$4:$C$1500=$C13)*('系统实绩导入'!$D$4:$D$1500=$D13)*('系统实绩导入'!$F$4:$F$1500="实绩毛利")*('系统实绩导入'!$G$3:$R$3=$F$1)*'系统实绩导入'!$G$4:$R$1500)) | G13: =IF($B13="","",IFERROR(F13/E13,"")) | H13: =IF($B13="","",SUMPRODUCT(('目标填报'!$B$4:$B$1500=$B13)*('目标填报'!$C$4:$C$1500=$C13)*('目标填报'!$D$4:$D$1500=$D13)*('目标填报'!$F$4:$F$1500="销售目标额")*('目标填报'!$G$3:$R$3=$F$1)*'目标填报'!$G$4:$R$1500)) | I13: =IF($B13="","",IFERROR(E13/H13,"")) | J13: =IF($B13="","",SUMPRODUCT(('系统实绩导入'!$B$4:$B$1500=$B13)*('系统实绩导入'!$C$4:$C$1500=$C13)*('系统实绩导入'!$D$4:$D$1500=$D13)*('系统实绩导入'!$F$4:$F$1500="实绩销售额")*('系统实绩导入'!$G$3:$R$3<=$F$1)*'系统实绩导入'!$G$4:$R$1500)) | K13: =IF($B13="","",SUMPRODUCT(('系统实绩导入'!$B$4:$B$1500=$B13)*('系统实绩导入'!$C$4:$C$1500=$C13)*('系统实绩导入'!$D$4:$D$1500=$D13)*('系统实绩导入'!$F$4:$F$1500="实绩毛利")*('系统实绩导入'!$G$3:$R$3<=$F$1)*'系统实绩导入'!$G$4:$R$1500)) | L13: =IF($B13="","",IFERROR(K13/J13,"")) | M13: =IF($B13="","",SUMIFS('目标填报'!$S$4:$S$1500,'目标填报'!$B$4:$B$1500,$B13,'目标填报'!$C$4:$C$1500,$C13,'目标填报'!$D$4:$D$1500,$D13,'目标填报'!$F$4:$F$1500,"销售目标额")) | N13: =IF($B13="","",IFERROR(J13/M13,"")) | O13: =IF($B13="","",J13-M13) | P13: =IF($B13="","",SUMPRODUCT(('目标填报'!$B$4:$B$1500=$B13)*('目标填报'!$C$4:$C$1500=$C13)*('目标填报'!$D$4:$D$1500=$D13)*('目标填报'!$F$4:$F$1500="在手订单")*('目标填报'!$G$3:$R$3=$F$1)*'目标填报'!$G$4:$R$1500)) | Q13: =IF($B13="","",SUMPRODUCT(('目标填报'!$B$4:$B$1500=$B13)*('目标填报'!$C$4:$C$1500=$C13)*('目标填报'!$D$4:$D$1500=$D13)*('目标填报'!$F$4:$F$1500="在手订单目标")*('目标填报'!$G$3:$R$3=$F$1)*'目标填报'!$G$4:$R$1500)) | R13: =IF($B13="","",IFERROR(P13/Q13,"")) | S13: =IF($B13="","",SUMPRODUCT(('目标填报'!$B$4:$B$1500=$B13)*('目标填报'!$C$4:$C$1500=$C13)*('目标填报'!$D$4:$D$1500=$D13)*('目标填报'!$F$4:$F$1500="目标客户机会")*('目标填报'!$G$3:$R$3=$F$1)*'目标填报'!$G$4:$R$1500)) | T13: =IF($B13="","",SUMPRODUCT(('目标填报'!$B$4:$B$1500=$B13)*('目标填报'!$C$4:$C$1500=$C13)*('目标填报'!$D$4:$D$1500=$D13)*('目标填报'!$F$4:$F$1500="目标客户机会目标")*('目标填报'!$G$3:$R$3=$F$1)*'目标填报'!$G$4:$R$1500)) | U13: =IF($B13="","",IFERROR(S13/T13,"")) | V13: =IF($B13="","",P13+S13) | W13: =IF($B13="","",M13-J13) | X13: =IF($B13="","",IFERROR(V13/W13,"")) | Y13: =IF($B13="","",V13-W13)
A14: =IF($B14="","",ROW()-3) | B14: =IF(10+1>COUNTA('维度字典'!$C$2:$C$200)*COUNTA('维度字典'!$A$2:$A$200)*COUNTA('维度字典'!$E$2:$E$200),"",INDEX('维度字典'!$C$2:$C$200,MOD(INT(10/(COUNTA('维度字典'!$E$2:$E$200)*COUNTA('维度字典'!$A$2:$A$200))),COUNTA('维度字典'!$C$2:$C$200))+1)) | C14: =IF($B14="","",INDEX('维度字典'!$A$2:$A$200,MOD(INT(10/COUNTA('维度字典'!$E$2:$E$200)),COUNTA('维度字典'!$A$2:$A$200))+1)) | D14: =IF($B14="","",INDEX('维度字典'!$E$2:$E$200,MOD(10,COUNTA('维度字典'!$E$2:$E$200))+1)) | E14: =IF($B14="","",SUMPRODUCT(('系统实绩导入'!$B$4:$B$1500=$B14)*('系统实绩导入'!$C$4:$C$1500=$C14)*('系统实绩导入'!$D$4:$D$1500=$D14)*('系统实绩导入'!$F$4:$F$1500="实绩销售额")*('系统实绩导入'!$G$3:$R$3=$F$1)*'系统实绩导入'!$G$4:$R$1500)) | F14: =IF($B14="","",SUMPRODUCT(('系统实绩导入'!$B$4:$B$1500=$B14)*('系统实绩导入'!$C$4:$C$1500=$C14)*('系统实绩导入'!$D$4:$D$1500=$D14)*('系统实绩导入'!$F$4:$F$1500="实绩毛利")*('系统实绩导入'!$G$3:$R$3=$F$1)*'系统实绩导入'!$G$4:$R$1500)) | G14: =IF($B14="","",IFERROR(F14/E14,"")) | H14: =IF($B14="","",SUMPRODUCT(('目标填报'!$B$4:$B$1500=$B14)*('目标填报'!$C$4:$C$1500=$C14)*('目标填报'!$D$4:$D$1500=$D14)*('目标填报'!$F$4:$F$1500="销售目标额")*('目标填报'!$G$3:$R$3=$F$1)*'目标填报'!$G$4:$R$1500)) | I14: =IF($B14="","",IFERROR(E14/H14,"")) | J14: =IF($B14="","",SUMPRODUCT(('系统实绩导入'!$B$4:$B$1500=$B14)*('系统实绩导入'!$C$4:$C$1500=$C14)*('系统实绩导入'!$D$4:$D$1500=$D14)*('系统实绩导入'!$F$4:$F$1500="实绩销售额")*('系统实绩导入'!$G$3:$R$3<=$F$1)*'系统实绩导入'!$G$4:$R$1500)) | K14: =IF($B14="","",SUMPRODUCT(('系统实绩导入'!$B$4:$B$1500=$B14)*('系统实绩导入'!$C$4:$C$1500=$C14)*('系统实绩导入'!$D$4:$D$1500=$D14)*('系统实绩导入'!$F$4:$F$1500="实绩毛利")*('系统实绩导入'!$G$3:$R$3<=$F$1)*'系统实绩导入'!$G$4:$R$1500)) | L14: =IF($B14="","",IFERROR(K14/J14,"")) | M14: =IF($B14="","",SUMIFS('目标填报'!$S$4:$S$1500,'目标填报'!$B$4:$B$1500,$B14,'目标填报'!$C$4:$C$1500,$C14,'目标填报'!$D$4:$D$1500,$D14,'目标填报'!$F$4:$F$1500,"销售目标额")) | N14: =IF($B14="","",IFERROR(J14/M14,"")) | O14: =IF($B14="","",J14-M14) | P14: =IF($B14="","",SUMPRODUCT(('目标填报'!$B$4:$B$1500=$B14)*('目标填报'!$C$4:$C$1500=$C14)*('目标填报'!$D$4:$D$1500=$D14)*('目标填报'!$F$4:$F$1500="在手订单")*('目标填报'!$G$3:$R$3=$F$1)*'目标填报'!$G$4:$R$1500)) | Q14: =IF($B14="","",SUMPRODUCT(('目标填报'!$B$4:$B$1500=$B14)*('目标填报'!$C$4:$C$1500=$C14)*('目标填报'!$D$4:$D$1500=$D14)*('目标填报'!$F$4:$F$1500="在手订单目标")*('目标填报'!$G$3:$R$3=$F$1)*'目标填报'!$G$4:$R$1500)) | R14: =IF($B14="","",IFERROR(P14/Q14,"")) | S14: =IF($B14="","",SUMPRODUCT(('目标填报'!$B$4:$B$1500=$B14)*('目标填报'!$C$4:$C$1500=$C14)*('目标填报'!$D$4:$D$1500=$D14)*('目标填报'!$F$4:$F$1500="目标客户机会")*('目标填报'!$G$3:$R$3=$F$1)*'目标填报'!$G$4:$R$1500)) | T14: =IF($B14="","",SUMPRODUCT(('目标填报'!$B$4:$B$1500=$B14)*('目标填报'!$C$4:$C$1500=$C14)*('目标填报'!$D$4:$D$1500=$D14)*('目标填报'!$F$4:$F$1500="目标客户机会目标")*('目标填报'!$G$3:$R$3=$F$1)*'目标填报'!$G$4:$R$1500)) | U14: =IF($B14="","",IFERROR(S14/T14,"")) | V14: =IF($B14="","",P14+S14) | W14: =IF($B14="","",M14-J14) | X14: =IF($B14="","",IFERROR(V14/W14,"")) | Y14: =IF($B14="","",V14-W14)
A15: =IF($B15="","",ROW()-3) | B15: =IF(11+1>COUNTA('维度字典'!$C$2:$C$200)*COUNTA('维度字典'!$A$2:$A$200)*COUNTA('维度字典'!$E$2:$E$200),"",INDEX('维度字典'!$C$2:$C$200,MOD(INT(11/(COUNTA('维度字典'!$E$2:$E$200)*COUNTA('维度字典'!$A$2:$A$200))),COUNTA('维度字典'!$C$2:$C$200))+1)) | C15: =IF($B15="","",INDEX('维度字典'!$A$2:$A$200,MOD(INT(11/COUNTA('维度字典'!$E$2:$E$200)),COUNTA('维度字典'!$A$2:$A$200))+1)) | D15: =IF($B15="","",INDEX('维度字典'!$E$2:$E$200,MOD(11,COUNTA('维度字典'!$E$2:$E$200))+1)) | E15: =IF($B15="","",SUMPRODUCT(('系统实绩导入'!$B$4:$B$1500=$B15)*('系统实绩导入'!$C$4:$C$1500=$C15)*('系统实绩导入'!$D$4:$D$1500=$D15)*('系统实绩导入'!$F$4:$F$1500="实绩销售额")*('系统实绩导入'!$G$3:$R$3=$F$1)*'系统实绩导入'!$G$4:$R$1500)) | F15: =IF($B15="","",SUMPRODUCT(('系统实绩导入'!$B$4:$B$1500=$B15)*('系统实绩导入'!$C$4:$C$1500=$C15)*('系统实绩导入'!$D$4:$D$1500=$D15)*('系统实绩导入'!$F$4:$F$1500="实绩毛利")*('系统实绩导入'!$G$3:$R$3=$F$1)*'系统实绩导入'!$G$4:$R$1500)) | G15: =IF($B15="","",IFERROR(F15/E15,"")) | H15: =IF($B15="","",SUMPRODUCT(('目标填报'!$B$4:$B$1500=$B15)*('目标填报'!$C$4:$C$1500=$C15)*('目标填报'!$D$4:$D$1500=$D15)*('目标填报'!$F$4:$F$1500="销售目标额")*('目标填报'!$G$3:$R$3=$F$1)*'目标填报'!$G$4:$R$1500)) | I15: =IF($B15="","",IFERROR(E15/H15,"")) | J15: =IF($B15="","",SUMPRODUCT(('系统实绩导入'!$B$4:$B$1500=$B15)*('系统实绩导入'!$C$4:$C$1500=$C15)*('系统实绩导入'!$D$4:$D$1500=$D15)*('系统实绩导入'!$F$4:$F$1500="实绩销售额")*('系统实绩导入'!$G$3:$R$3<=$F$1)*'系统实绩导入'!$G$4:$R$1500)) | K15: =IF($B15="","",SUMPRODUCT(('系统实绩导入'!$B$4:$B$1500=$B15)*('系统实绩导入'!$C$4:$C$1500=$C15)*('系统实绩导入'!$D$4:$D$1500=$D15)*('系统实绩导入'!$F$4:$F$1500="实绩毛利")*('系统实绩导入'!$G$3:$R$3<=$F$1)*'系统实绩导入'!$G$4:$R$1500)) | L15: =IF($B15="","",IFERROR(K15/J15,"")) | M15: =IF($B15="","",SUMIFS('目标填报'!$S$4:$S$1500,'目标填报'!$B$4:$B$1500,$B15,'目标填报'!$C$4:$C$1500,$C15,'目标填报'!$D$4:$D$1500,$D15,'目标填报'!$F$4:$F$1500,"销售目标额")) | N15: =IF($B15="","",IFERROR(J15/M15,"")) | O15: =IF($B15="","",J15-M15) | P15: =IF($B15="","",SUMPRODUCT(('目标填报'!$B$4:$B$1500=$B15)*('目标填报'!$C$4:$C$1500=$C15)*('目标填报'!$D$4:$D$1500=$D15)*('目标填报'!$F$4:$F$1500="在手订单")*('目标填报'!$G$3:$R$3=$F$1)*'目标填报'!$G$4:$R$1500)) | Q15: =IF($B15="","",SUMPRODUCT(('目标填报'!$B$4:$B$1500=$B15)*('目标填报'!$C$4:$C$1500=$C15)*('目标填报'!$D$4:$D$1500=$D15)*('目标填报'!$F$4:$F$1500="在手订单目标")*('目标填报'!$G$3:$R$3=$F$1)*'目标填报'!$G$4:$R$1500)) | R15: =IF($B15="","",IFERROR(P15/Q15,"")) | S15: =IF($B15="","",SUMPRODUCT(('目标填报'!$B$4:$B$1500=$B15)*('目标填报'!$C$4:$C$1500=$C15)*('目标填报'!$D$4:$D$1500=$D15)*('目标填报'!$F$4:$F$1500="目标客户机会")*('目标填报'!$G$3:$R$3=$F$1)*'目标填报'!$G$4:$R$1500)) | T15: =IF($B15="","",SUMPRODUCT(('目标填报'!$B$4:$B$1500=$B15)*('目标填报'!$C$4:$C$1500=$C15)*('目标填报'!$D$4:$D$1500=$D15)*('目标填报'!$F$4:$F$1500="目标客户机会目标")*('目标填报'!$G$3:$R$3=$F$1)*'目标填报'!$G$4:$R$1500)) | U15: =IF($B15="","",IFERROR(S15/T15,"")) | V15: =IF($B15="","",P15+S15) | W15: =IF($B15="","",M15-J15) | X15: =IF($B15="","",IFERROR(V15/W15,"")) | Y15: =IF($B15="","",V15-W15)
